Workbook

Sheet Purchase Orders
A1: DC_CODE | B1: PURCH_ORDER_NUMBER | C1: PURCH_ORDER_DATE | D1: EXPECTED_DATE | E1: SUPPLIER_CODE | F1: SUPPLIER NAME | G1: PURCH_ORDER_LINE | H1: EAN_NO | I1: PRODUCT_CODE | J1: PRODUCT_DESCRIPTION | K1: VENDOR_ITEM_CODE | L1: ORDERING_UNIT | M1: QTY_PER_PACK_OF_ORDERING_UOM | N1: NO_OF_PACKS_ORDERED | O1: TOTAL_QUANTITY | P1: CLOSING_STOCK | Q1: MRP_PER_UNIT | R1: LANDING_COST_INCL_TAX_PER_UNIT | S1: SALES_TAX | T1: COST_PRICE_INCL_TAX_PER_PO_OU | U1: TAX_PER | V1: CURRENCY | W1: HSN | X1: MASTER PRODUCT CODE | Y1: Order type | Z1: S | AA1: M | AB1: L | AC1: XL | AD1: XXL | AE1: SKU | AF1: Colour | AG1: location | AH1: RP DESCRPTION
A2: SZAF | B2: 5114202424 | C2: 01.05.2026 | D2: 23.07.2026 | E2: 10337044 | F2: UNITED TEXTILE MILLS PRIVATE LIMITE | G2: 1 | H2: 8909490134375 | I2: 441811508001 | J2: KRTS-APWN26-GETKRTSFUT61, OFF WHITE, 2XL | L2: EA | M2: 1 | N2: 30 | O2: 30 | Q2: 314.7 | R2: 314.7 | S2: 472.05 | T2: 9441 | U2: 5 | V2: INR | X2: =IF(ISNUMBER(VALUE(LEFT(J2,1))),LEFT(J2,MIN(IFERROR(FIND("A",UPPER(J2)),LEN(J2)+1),IFERROR(FIND("B",UPPER(J2)),LEN(J2)+1),IFERROR(FIND("C",UPPER(J2)),LEN(J2)+1),IFERROR(FIND("D",UPPER(J2)),LEN(J2)+1),IFERROR(FIND("E",UPPER(J2)),LEN(J2)+1),IFERROR(FIND("F",UPPER(J2)),LEN(J2)+1),IFERROR(FIND("G",UPPER(J2)),LEN(J2)+1),IFERROR(FIND("H",UPPER(J2)),LEN(J2)+1),IFERROR(FIND("I",UPPER(J2)),LEN(J2)+1),IFERROR(FIND("J",UPPER(J2)),LEN(J2)+1),IFERROR(FIND("K",UPPER(J2)),LEN(J2)+1),IFERROR(FIND("L",UPPER(J2)),LEN(J2)+1),IFERROR(FIND("M",UPPER(J2)),LEN(J2)+1),IFERROR(FIND("N",UPPER(J2)),LEN(J2)+1),IFERROR(FIND("O",UPPER(J2)),LEN(J2)+1),IFERROR(FIND("P",UPPER(J2)),LEN(J2)+1),IFERROR(FIND("Q",UPPER(J2)),LEN(J2)+1),IFERROR(FIND("R",UPPER(J2)),LEN(J2)+1),IFERROR(FIND("S",UPPER(J2)),LEN(J2)+1),IFERROR(FIND("T",UPPER(J2)),LEN(J2)+1),IFERROR(FIND("U",UPPER(J2)),LEN(J2)+1),IFERROR(FIND("V",UPPER(J2)),LEN(J2)+1),IFERROR(FIND("W",UPPER(J2)),LEN(J2)+1),IFERROR(FIND("X",UPPER(J2)),LEN(J2)+1),IFERROR(FIND("Y",UPPER(J2)),LEN(J2)+1),IFERROR(FIND("Z",UPPER(J2)),LEN(J2)+1))-1),LEFT(TEXT(I2,"0"),LEN(TEXT(I2,"0"))-3)) -> 441811508 | Y2: =IF(ISNUMBER(SEARCH("(RP)",J2)),"RP","DC") -> DC | Z2: =IF(ISNUMBER(SEARCH("(RP)",J2)),O2,IF(RIGHT(TRIM(J2),3)=", S",O2,0)) -> 0 | AA2: =IF(ISNUMBER(SEARCH("(RP)",J2)),O2,IF(RIGHT(TRIM(J2),3)=", M",O2,0)) -> 0 | AB2: =IF(ISNUMBER(SEARCH("(RP)",J2)),O2,IF(RIGHT(TRIM(J2),3)=", L",O2,0)) -> 0 | AC2: =IF(ISNUMBER(SEARCH("(RP)",J2)),O2,IF(RIGHT(TRIM(J2),4)=", XL",O2,0)) -> 0 | AD2: =IF(ISNUMBER(SEARCH("(RP)",J2)),O2,IF(OR(RIGHT(TRIM(J2),5)=", XXL",RIGHT(TRIM(J2),5)=", 2XL"),O2,0)) -> 30 | AE2: {=IFERROR(_xlfn.XLOOKUP(H2,Sheet1!$G:$G,Sheet1!$F:$F),IFERROR(_xlfn.XLOOKUP(1,(--($X$2:$X$1074=X2))*(--ISNUMBER(MATCH($H$2:$H$1074,Sheet1!$G:$G,0))),_xlfn.XLOOKUP($H$2:$H$1074,Sheet1!$G:$G,Sheet1!$F:$F,"")),"NOT FOUND"))} -> GETKRTSFUT6125 | AF2: =IFERROR(IF(ISNUMBER(SEARCH("(RP)",J2)),TRIM(SUBSTITUTE(MID(J2,10,LEN(J2)),"(RP)","")),TRIM(MID(J2,FIND(",",J2)+1,FIND(",",J2,FIND(",",J2)+1)-FIND(",",J2)-1))),"") -> OFF WHITE | AG2: =IF(A2="SZAF","Bangalore",IF(A2="SAEX","JHAJJAR",IF(A2="S0EU","HARIPAL",""))) -> Bangalore | AH2: =IF(OR(J2="",AE2="",AE2="NOT FOUND"),"",IF(Y2="RP",IFERROR(LEFT(_xlfn.XLOOKUP(AE2,Sheet1!$F:$F,Sheet1!$W:$W),FIND("-",_xlfn.XLOOKUP(AE2,Sheet1!$F:$F,Sheet1!$W:$W),FIND("-",_xlfn.XLOOKUP(AE2,Sheet1!$F:$F,Sheet1!$W:$W))+1))&AE2,"NOT FOUND"),LEFT(J2,FIND("-",J2,FIND("-",J2)+1))&AE2)) -> KRTS-APWN26-GETKRTSFUT6125
A3: SZAF | B3: 5114202424 | C3: 01.05.2026 | D3: 23.07.2026 | E3: 10337044 | F3: UNITED TEXTILE MILLS PRIVATE LIMITE | G3: 2 | H3: 8909490134382 | I3: 441811508002 | J3: KRTS-APWN26-GETKRTSFUT6125, OFF WHITE, L | L3: EA | M3: 1 | N3: 257 | O3: 257 | Q3: 314.7 | R3: 314.7 | S3: 4043.9 | T3: 80877.9 | U3: 5 | V3: INR | X3: =IF(ISNUMBER(VALUE(LEFT(J3,1))),LEFT(J3,MIN(IFERROR(FIND("A",UPPER(J3)),LEN(J3)+1),IFERROR(FIND("B",UPPER(J3)),LEN(J3)+1),IFERROR(FIND("C",UPPER(J3)),LEN(J3)+1),IFERROR(FIND("D",UPPER(J3)),LEN(J3)+1),IFERROR(FIND("E",UPPER(J3)),LEN(J3)+1),IFERROR(FIND("F",UPPER(J3)),LEN(J3)+1),IFERROR(FIND("G",UPPER(J3)),LEN(J3)+1),IFERROR(FIND("H",UPPER(J3)),LEN(J3)+1),IFERROR(FIND("I",UPPER(J3)),LEN(J3)+1),IFERROR(FIND("J",UPPER(J3)),LEN(J3)+1),IFERROR(FIND("K",UPPER(J3)),LEN(J3)+1),IFERROR(FIND("L",UPPER(J3)),LEN(J3)+1),IFERROR(FIND("M",UPPER(J3)),LEN(J3)+1),IFERROR(FIND("N",UPPER(J3)),LEN(J3)+1),IFERROR(FIND("O",UPPER(J3)),LEN(J3)+1),IFERROR(FIND("P",UPPER(J3)),LEN(J3)+1),IFERROR(FIND("Q",UPPER(J3)),LEN(J3)+1),IFERROR(FIND("R",UPPER(J3)),LEN(J3)+1),IFERROR(FIND("S",UPPER(J3)),LEN(J3)+1),IFERROR(FIND("T",UPPER(J3)),LEN(J3)+1),IFERROR(FIND("U",UPPER(J3)),LEN(J3)+1),IFERROR(FIND("V",UPPER(J3)),LEN(J3)+1),IFERROR(FIND("W",UPPER(J3)),LEN(J3)+1),IFERROR(FIND("X",UPPER(J3)),LEN(J3)+1),IFERROR(FIND("Y",UPPER(J3)),LEN(J3)+1),IFERROR(FIND("Z",UPPER(J3)),LEN(J3)+1))-1),LEFT(TEXT(I3,"0"),LEN(TEXT(I3,"0"))-3)) -> 441811508 | Y3: =IF(ISNUMBER(SEARCH("(RP)",J3)),"RP","DC") -> DC | Z3: =IF(ISNUMBER(SEARCH("(RP)",J3)),O3,IF(RIGHT(TRIM(J3),3)=", S",O3,0)) -> 0 | AA3: =IF(ISNUMBER(SEARCH("(RP)",J3)),O3,IF(RIGHT(TRIM(J3),3)=", M",O3,0)) -> 0 | AB3: =IF(ISNUMBER(SEARCH("(RP)",J3)),O3,IF(RIGHT(TRIM(J3),3)=", L",O3,0)) -> 257 | AC3: =IF(ISNUMBER(SEARCH("(RP)",J3)),O3,IF(RIGHT(TRIM(J3),4)=", XL",O3,0)) -> 0 | AD3: =IF(ISNUMBER(SEARCH("(RP)",J3)),O3,IF(OR(RIGHT(TRIM(J3),5)=", XXL",RIGHT(TRIM(J3),5)=", 2XL"),O3,0)) -> 0 | AE3: {=IFERROR(_xlfn.XLOOKUP(H3,Sheet1!$G:$G,Sheet1!$F:$F),IFERROR(_xlfn.XLOOKUP(1,(--($X$2:$X$1074=X3))*(--ISNUMBER(MATCH($H$2:$H$1074,Sheet1!$G:$G,0))),_xlfn.XLOOKUP($H$2:$H$1074,Sheet1!$G:$G,Sheet1!$F:$F,"")),"NOT FOUND"))} -> GETKRTSFUT6125 | AF3: =IFERROR(IF(ISNUMBER(SEARCH("(RP)",J3)),TRIM(SUBSTITUTE(MID(J3,10,LEN(J3)),"(RP)","")),TRIM(MID(J3,FIND(",",J3)+1,FIND(",",J3,FIND(",",J3)+1)-FIND(",",J3)-1))),"") -> OFF WHITE | AG3: =IF(A3="SZAF","Bangalore",IF(A3="SAEX","JHAJJAR",IF(A3="S0EU","HARIPAL",""))) -> Bangalore | AH3: =IF(OR(J3="",AE3="",AE3="NOT FOUND"),"",IF(Y3="RP",IFERROR(LEFT(_xlfn.XLOOKUP(AE3,Sheet1!$F:$F,Sheet1!$W:$W),FIND("-",_xlfn.XLOOKUP(AE3,Sheet1!$F:$F,Sheet1!$W:$W),FIND("-",_xlfn.XLOOKUP(AE3,Sheet1!$F:$F,Sheet1!$W:$W))+1))&AE3,"NOT FOUND"),LEFT(J3,FIND("-",J3,FIND("-",J3)+1))&AE3)) -> KRTS-APWN26-GETKRTSFUT6125
A4: SZAF | B4: 5114202424 | C4: 01.05.2026 | D4: 23.07.2026 | E4: 10337044 | F4: UNITED TEXTILE MILLS PRIVATE LIMITE | G4: 3 | H4: 8909490134399 | I4: 441811508003 | J4: KRTS-APWN26-GETKRTSFUT6125, OFF WHITE, M | L4: EA | M4: 1 | N4: 257 | O4: 257 | Q4: 314.7 | R4: 314.7 | S4: 4043.9 | T4: 80877.9 | U4: 5 | V4: INR | X4: =IF(ISNUMBER(VALUE(LEFT(J4,1))),LEFT(J4,MIN(IFERROR(FIND("A",UPPER(J4)),LEN(J4)+1),IFERROR(FIND("B",UPPER(J4)),LEN(J4)+1),IFERROR(FIND("C",UPPER(J4)),LEN(J4)+1),IFERROR(FIND("D",UPPER(J4)),LEN(J4)+1),IFERROR(FIND("E",UPPER(J4)),LEN(J4)+1),IFERROR(FIND("F",UPPER(J4)),LEN(J4)+1),IFERROR(FIND("G",UPPER(J4)),LEN(J4)+1),IFERROR(FIND("H",UPPER(J4)),LEN(J4)+1),IFERROR(FIND("I",UPPER(J4)),LEN(J4)+1),IFERROR(FIND("J",UPPER(J4)),LEN(J4)+1),IFERROR(FIND("K",UPPER(J4)),LEN(J4)+1),IFERROR(FIND("L",UPPER(J4)),LEN(J4)+1),IFERROR(FIND("M",UPPER(J4)),LEN(J4)+1),IFERROR(FIND("N",UPPER(J4)),LEN(J4)+1),IFERROR(FIND("O",UPPER(J4)),LEN(J4)+1),IFERROR(FIND("P",UPPER(J4)),LEN(J4)+1),IFERROR(FIND("Q",UPPER(J4)),LEN(J4)+1),IFERROR(FIND("R",UPPER(J4)),LEN(J4)+1),IFERROR(FIND("S",UPPER(J4)),LEN(J4)+1),IFERROR(FIND("T",UPPER(J4)),LEN(J4)+1),IFERROR(FIND("U",UPPER(J4)),LEN(J4)+1),IFERROR(FIND("V",UPPER(J4)),LEN(J4)+1),IFERROR(FIND("W",UPPER(J4)),LEN(J4)+1),IFERROR(FIND("X",UPPER(J4)),LEN(J4)+1),IFERROR(FIND("Y",UPPER(J4)),LEN(J4)+1),IFERROR(FIND("Z",UPPER(J4)),LEN(J4)+1))-1),LEFT(TEXT(I4,"0"),LEN(TEXT(I4,"0"))-3)) -> 441811508 | Y4: =IF(ISNUMBER(SEARCH("(RP)",J4)),"RP","DC") -> DC | Z4: =IF(ISNUMBER(SEARCH("(RP)",J4)),O4,IF(RIGHT(TRIM(J4),3)=", S",O4,0)) -> 0 | AA4: =IF(ISNUMBER(SEARCH("(RP)",J4)),O4,IF(RIGHT(TRIM(J4),3)=", M",O4,0)) -> 257 | AB4: =IF(ISNUMBER(SEARCH("(RP)",J4)),O4,IF(RIGHT(TRIM(J4),3)=", L",O4,0)) -> 0 | AC4: =IF(ISNUMBER(SEARCH("(RP)",J4)),O4,IF(RIGHT(TRIM(J4),4)=", XL",O4,0)) -> 0 | AD4: =IF(ISNUMBER(SEARCH("(RP)",J4)),O4,IF(OR(RIGHT(TRIM(J4),5)=", XXL",RIGHT(TRIM(J4),5)=", 2XL"),O4,0)) -> 0 | AE4: {=IFERROR(_xlfn.XLOOKUP(H4,Sheet1!$G:$G,Sheet1!$F:$F),IFERROR(_xlfn.XLOOKUP(1,(--($X$2:$X$1074=X4))*(--ISNUMBER(MATCH($H$2:$H$1074,Sheet1!$G:$G,0))),_xlfn.XLOOKUP($H$2:$H$1074,Sheet1!$G:$G,Sheet1!$F:$F,"")),"NOT FOUND"))} -> GETKRTSFUT6125 | AF4: =IFERROR(IF(ISNUMBER(SEARCH("(RP)",J4)),TRIM(SUBSTITUTE(MID(J4,10,LEN(J4)),"(RP)","")),TRIM(MID(J4,FIND(",",J4)+1,FIND(",",J4,FIND(",",J4)+1)-FIND(",",J4)-1))),"") -> OFF WHITE | AG4: =IF(A4="SZAF","Bangalore",IF(A4="SAEX","JHAJJAR",IF(A4="S0EU","HARIPAL",""))) -> Bangalore | AH4: =IF(OR(J4="",AE4="",AE4="NOT FOUND"),"",IF(Y4="RP",IFERROR(LEFT(_xlfn.XLOOKUP(AE4,Sheet1!$F:$F,Sheet1!$W:$W),FIND("-",_xlfn.XLOOKUP(AE4,Sheet1!$F:$F,Sheet1!$W:$W),FIND("-",_xlfn.XLOOKUP(AE4,Sheet1!$F:$F,Sheet1!$W:$W))+1))&AE4,"NOT FOUND"),LEFT(J4,FIND("-",J4,FIND("-",J4)+1))&AE4)) -> KRTS-APWN26-GETKRTSFUT6125
A5: SZAF | B5: 5114202424 | C5: 01.05.2026 | D5: 23.07.2026 | E5: 10337044 | F5: UNITED TEXTILE MILLS PRIVATE LIMITE | G5: 4 | H5: 8909490134405 | I5: 441811508004 | J5: KRTS-APWN26-GETKRTSFUT6125, OFF WHITE, S | L5: EA | M5: 1 | N5: 30 | O5: 30 | Q5: 314.7 | R5: 314.7 | S5: 472.05 | T5: 9441 | U5: 5 | V5: INR | X5: =IF(ISNUMBER(VALUE(LEFT(J5,1))),LEFT(J5,MIN(IFERROR(FIND("A",UPPER(J5)),LEN(J5)+1),IFERROR(FIND("B",UPPER(J5)),LEN(J5)+1),IFERROR(FIND("C",UPPER(J5)),LEN(J5)+1),IFERROR(FIND("D",UPPER(J5)),LEN(J5)+1),IFERROR(FIND("E",UPPER(J5)),LEN(J5)+1),IFERROR(FIND("F",UPPER(J5)),LEN(J5)+1),IFERROR(FIND("G",UPPER(J5)),LEN(J5)+1),IFERROR(FIND("H",UPPER(J5)),LEN(J5)+1),IFERROR(FIND("I",UPPER(J5)),LEN(J5)+1),IFERROR(FIND("J",UPPER(J5)),LEN(J5)+1),IFERROR(FIND("K",UPPER(J5)),LEN(J5)+1),IFERROR(FIND("L",UPPER(J5)),LEN(J5)+1),IFERROR(FIND("M",UPPER(J5)),LEN(J5)+1),IFERROR(FIND("N",UPPER(J5)),LEN(J5)+1),IFERROR(FIND("O",UPPER(J5)),LEN(J5)+1),IFERROR(FIND("P",UPPER(J5)),LEN(J5)+1),IFERROR(FIND("Q",UPPER(J5)),LEN(J5)+1),IFERROR(FIND("R",UPPER(J5)),LEN(J5)+1),IFERROR(FIND("S",UPPER(J5)),LEN(J5)+1),IFERROR(FIND("T",UPPER(J5)),LEN(J5)+1),IFERROR(FIND("U",UPPER(J5)),LEN(J5)+1),IFERROR(FIND("V",UPPER(J5)),LEN(J5)+1),IFERROR(FIND("W",UPPER(J5)),LEN(J5)+1),IFERROR(FIND("X",UPPER(J5)),LEN(J5)+1),IFERROR(FIND("Y",UPPER(J5)),LEN(J5)+1),IFERROR(FIND("Z",UPPER(J5)),LEN(J5)+1))-1),LEFT(TEXT(I5,"0"),LEN(TEXT(I5,"0"))-3)) -> 441811508 | Y5: =IF(ISNUMBER(SEARCH("(RP)",J5)),"RP","DC") -> DC | Z5: =IF(ISNUMBER(SEARCH("(RP)",J5)),O5,IF(RIGHT(TRIM(J5),3)=", S",O5,0)) -> 30 | AA5: =IF(ISNUMBER(SEARCH("(RP)",J5)),O5,IF(RIGHT(TRIM(J5),3)=", M",O5,0)) -> 0 | AB5: =IF(ISNUMBER(SEARCH("(RP)",J5)),O5,IF(RIGHT(TRIM(J5),3)=", L",O5,0)) -> 0 | AC5: =IF(ISNUMBER(SEARCH("(RP)",J5)),O5,IF(RIGHT(TRIM(J5),4)=", XL",O5,0)) -> 0 | AD5: =IF(ISNUMBER(SEARCH("(RP)",J5)),O5,IF(OR(RIGHT(TRIM(J5),5)=", XXL",RIGHT(TRIM(J5),5)=", 2XL"),O5,0)) -> 0 | AE5: {=IFERROR(_xlfn.XLOOKUP(H5,Sheet1!$G:$G,Sheet1!$F:$F),IFERROR(_xlfn.XLOOKUP(1,(--($X$2:$X$1074=X5))*(--ISNUMBER(MATCH($H$2:$H$1074,Sheet1!$G:$G,0))),_xlfn.XLOOKUP($H$2:$H$1074,Sheet1!$G:$G,Sheet1!$F:$F,"")),"NOT FOUND"))} -> GETKRTSFUT6125 | AF5: =IFERROR(IF(ISNUMBER(SEARCH("(RP)",J5)),TRIM(SUBSTITUTE(MID(J5,10,LEN(J5)),"(RP)","")),TRIM(MID(J5,FIND(",",J5)+1,FIND(",",J5,FIND(",",J5)+1)-FIND(",",J5)-1))),"") -> OFF WHITE | AG5: =IF(A5="SZAF","Bangalore",IF(A5="SAEX","JHAJJAR",IF(A5="S0EU","HARIPAL",""))) -> Bangalore | AH5: =IF(OR(J5="",AE5="",AE5="NOT FOUND"),"",IF(Y5="RP",IFERROR(LEFT(_xlfn.XLOOKUP(AE5,Sheet1!$F:$F,Sheet1!$W:$W),FIND("-",_xlfn.XLOOKUP(AE5,Sheet1!$F:$F,Sheet1!$W:$W),FIND("-",_xlfn.XLOOKUP(AE5,Sheet1!$F:$F,Sheet1!$W:$W))+1))&AE5,"NOT FOUND"),LEFT(J5,FIND("-",J5,FIND("-",J5)+1))&AE5)) -> KRTS-APWN26-GETKRTSFUT6125
A6: SZAF | B6: 5114202424 | C6: 01.05.2026 | D6: 23.07.2026 | E6: 10337044 | F6: UNITED TEXTILE MILLS PRIVATE LIMITE | G6: 5 | H6: 8909490134412 | I6: 441811508005 | J6: KRTS-APWN26-GETKRTSFUT612, OFF WHITE, XL | L6: EA | M6: 1 | N6: 217 | O6: 217 | Q6: 314.7 | R6: 314.7 | S6: 3414.5 | T6: 68289.9 | U6: 5 | V6: INR | X6: =IF(ISNUMBER(VALUE(LEFT(J6,1))),LEFT(J6,MIN(IFERROR(FIND("A",UPPER(J6)),LEN(J6)+1),IFERROR(FIND("B",UPPER(J6)),LEN(J6)+1),IFERROR(FIND("C",UPPER(J6)),LEN(J6)+1),IFERROR(FIND("D",UPPER(J6)),LEN(J6)+1),IFERROR(FIND("E",UPPER(J6)),LEN(J6)+1),IFERROR(FIND("F",UPPER(J6)),LEN(J6)+1),IFERROR(FIND("G",UPPER(J6)),LEN(J6)+1),IFERROR(FIND("H",UPPER(J6)),LEN(J6)+1),IFERROR(FIND("I",UPPER(J6)),LEN(J6)+1),IFERROR(FIND("J",UPPER(J6)),LEN(J6)+1),IFERROR(FIND("K",UPPER(J6)),LEN(J6)+1),IFERROR(FIND("L",UPPER(J6)),LEN(J6)+1),IFERROR(FIND("M",UPPER(J6)),LEN(J6)+1),IFERROR(FIND("N",UPPER(J6)),LEN(J6)+1),IFERROR(FIND("O",UPPER(J6)),LEN(J6)+1),IFERROR(FIND("P",UPPER(J6)),LEN(J6)+1),IFERROR(FIND("Q",UPPER(J6)),LEN(J6)+1),IFERROR(FIND("R",UPPER(J6)),LEN(J6)+1),IFERROR(FIND("S",UPPER(J6)),LEN(J6)+1),IFERROR(FIND("T",UPPER(J6)),LEN(J6)+1),IFERROR(FIND("U",UPPER(J6)),LEN(J6)+1),IFERROR(FIND("V",UPPER(J6)),LEN(J6)+1),IFERROR(FIND("W",UPPER(J6)),LEN(J6)+1),IFERROR(FIND("X",UPPER(J6)),LEN(J6)+1),IFERROR(FIND("Y",UPPER(J6)),LEN(J6)+1),IFERROR(FIND("Z",UPPER(J6)),LEN(J6)+1))-1),LEFT(TEXT(I6,"0"),LEN(TEXT(I6,"0"))-3)) -> 441811508 | Y6: =IF(ISNUMBER(SEARCH("(RP)",J6)),"RP","DC") -> DC | Z6: =IF(ISNUMBER(SEARCH("(RP)",J6)),O6,IF(RIGHT(TRIM(J6),3)=", S",O6,0)) -> 0 | AA6: =IF(ISNUMBER(SEARCH("(RP)",J6)),O6,IF(RIGHT(TRIM(J6),3)=", M",O6,0)) -> 0 | AB6: =IF(ISNUMBER(SEARCH("(RP)",J6)),O6,IF(RIGHT(TRIM(J6),3)=", L",O6,0)) -> 0 | AC6: =IF(ISNUMBER(SEARCH("(RP)",J6)),O6,IF(RIGHT(TRIM(J6),4)=", XL",O6,0)) -> 217 | AD6: =IF(ISNUMBER(SEARCH("(RP)",J6)),O6,IF(OR(RIGHT(TRIM(J6),5)=", XXL",RIGHT(TRIM(J6),5)=", 2XL"),O6,0)) -> 0 | AE6: {=IFERROR(_xlfn.XLOOKUP(H6,Sheet1!$G:$G,Sheet1!$F:$F),IFERROR(_xlfn.XLOOKUP(1,(--($X$2:$X$1074=X6))*(--ISNUMBER(MATCH($H$2:$H$1074,Sheet1!$G:$G,0))),_xlfn.XLOOKUP($H$2:$H$1074,Sheet1!$G:$G,Sheet1!$F:$F,"")),"NOT FOUND"))} -> GETKRTSFUT6125 | AF6: =IFERROR(IF(ISNUMBER(SEARCH("(RP)",J6)),TRIM(SUBSTITUTE(MID(J6,10,LEN(J6)),"(RP)","")),TRIM(MID(J6,FIND(",",J6)+1,FIND(",",J6,FIND(",",J6)+1)-FIND(",",J6)-1))),"") -> OFF WHITE | AG6: =IF(A6="SZAF","Bangalore",IF(A6="SAEX","JHAJJAR",IF(A6="S0EU","HARIPAL",""))) -> Bangalore | AH6: =IF(OR(J6="",AE6="",AE6="NOT FOUND"),"",IF(Y6="RP",IFERROR(LEFT(_xlfn.XLOOKUP(AE6,Sheet1!$F:$F,Sheet1!$W:$W),FIND("-",_xlfn.XLOOKUP(AE6,Sheet1!$F:$F,Sheet1!$W:$W),FIND("-",_xlfn.XLOOKUP(AE6,Sheet1!$F:$F,Sheet1!$W:$W))+1))&AE6,"NOT FOUND"),LEFT(J6,FIND("-",J6,FIND("-",J6)+1))&AE6)) -> KRTS-APWN26-GETKRTSFUT6125
A7: SAEX | B7: 5114202422 | C7: 01.05.2026 | D7: 23.07.2026 | E7: 10337044 | F7: UNITED TEXTILE MILLS PRIVATE LIMITE | G7: 1 | H7: 8909490134375 | I7: 441811508001 | J7: KRTS-APWN26-GETKRTSFUT61, OFF WHITE, 2XL | L7: EA | M7: 1 | N7: 30 | O7: 30 | Q7: 314.7 | R7: 314.7 | S7: 472.05 | T7: 9441 | U7: 5 | V7: INR | X7: =IF(ISNUMBER(VALUE(LEFT(J7,1))),LEFT(J7,MIN(IFERROR(FIND("A",UPPER(J7)),LEN(J7)+1),IFERROR(FIND("B",UPPER(J7)),LEN(J7)+1),IFERROR(FIND("C",UPPER(J7)),LEN(J7)+1),IFERROR(FIND("D",UPPER(J7)),LEN(J7)+1),IFERROR(FIND("E",UPPER(J7)),LEN(J7)+1),IFERROR(FIND("F",UPPER(J7)),LEN(J7)+1),IFERROR(FIND("G",UPPER(J7)),LEN(J7)+1),IFERROR(FIND("H",UPPER(J7)),LEN(J7)+1),IFERROR(FIND("I",UPPER(J7)),LEN(J7)+1),IFERROR(FIND("J",UPPER(J7)),LEN(J7)+1),IFERROR(FIND("K",UPPER(J7)),LEN(J7)+1),IFERROR(FIND("L",UPPER(J7)),LEN(J7)+1),IFERROR(FIND("M",UPPER(J7)),LEN(J7)+1),IFERROR(FIND("N",UPPER(J7)),LEN(J7)+1),IFERROR(FIND("O",UPPER(J7)),LEN(J7)+1),IFERROR(FIND("P",UPPER(J7)),LEN(J7)+1),IFERROR(FIND("Q",UPPER(J7)),LEN(J7)+1),IFERROR(FIND("R",UPPER(J7)),LEN(J7)+1),IFERROR(FIND("S",UPPER(J7)),LEN(J7)+1),IFERROR(FIND("T",UPPER(J7)),LEN(J7)+1),IFERROR(FIND("U",UPPER(J7)),LEN(J7)+1),IFERROR(FIND("V",UPPER(J7)),LEN(J7)+1),IFERROR(FIND("W",UPPER(J7)),LEN(J7)+1),IFERROR(FIND("X",UPPER(J7)),LEN(J7)+1),IFERROR(FIND("Y",UPPER(J7)),LEN(J7)+1),IFERROR(FIND("Z",UPPER(J7)),LEN(J7)+1))-1),LEFT(TEXT(I7,"0"),LEN(TEXT(I7,"0"))-3)) -> 441811508 | Y7: =IF(ISNUMBER(SEARCH("(RP)",J7)),"RP","DC") -> DC | Z7: =IF(ISNUMBER(SEARCH("(RP)",J7)),O7,IF(RIGHT(TRIM(J7),3)=", S",O7,0)) -> 0 | AA7: =IF(ISNUMBER(SEARCH("(RP)",J7)),O7,IF(RIGHT(TRIM(J7),3)=", M",O7,0)) -> 0 | AB7: =IF(ISNUMBER(SEARCH("(RP)",J7)),O7,IF(RIGHT(TRIM(J7),3)=", L",O7,0)) -> 0 | AC7: =IF(ISNUMBER(SEARCH("(RP)",J7)),O7,IF(RIGHT(TRIM(J7),4)=", XL",O7,0)) -> 0 | AD7: =IF(ISNUMBER(SEARCH("(RP)",J7)),O7,IF(OR(RIGHT(TRIM(J7),5)=", XXL",RIGHT(TRIM(J7),5)=", 2XL"),O7,0)) -> 30 | AE7: {=IFERROR(_xlfn.XLOOKUP(H7,Sheet1!$G:$G,Sheet1!$F:$F),IFERROR(_xlfn.XLOOKUP(1,(--($X$2:$X$1074=X7))*(--ISNUMBER(MATCH($H$2:$H$1074,Sheet1!$G:$G,0))),_xlfn.XLOOKUP($H$2:$H$1074,Sheet1!$G:$G,Sheet1!$F:$F,"")),"NOT FOUND"))} -> GETKRTSFUT6125 | AF7: =IFERROR(IF(ISNUMBER(SEARCH("(RP)",J7)),TRIM(SUBSTITUTE(MID(J7,10,LEN(J7)),"(RP)","")),TRIM(MID(J7,FIND(",",J7)+1,FIND(",",J7,FIND(",",J7)+1)-FIND(",",J7)-1))),"") -> OFF WHITE | AG7: =IF(A7="SZAF","Bangalore",IF(A7="SAEX","JHAJJAR",IF(A7="S0EU","HARIPAL",""))) -> JHAJJAR | AH7: =IF(OR(J7="",AE7="",AE7="NOT FOUND"),"",IF(Y7="RP",IFERROR(LEFT(_xlfn.XLOOKUP(AE7,Sheet1!$F:$F,Sheet1!$W:$W),FIND("-",_xlfn.XLOOKUP(AE7,Sheet1!$F:$F,Sheet1!$W:$W),FIND("-",_xlfn.XLOOKUP(AE7,Sheet1!$F:$F,Sheet1!$W:$W))+1))&AE7,"NOT FOUND"),LEFT(J7,FIND("-",J7,FIND("-",J7)+1))&AE7)) -> KRTS-APWN26-GETKRTSFUT6125
A8: SAEX | B8: 5114202422 | C8: 01.05.2026 | D8: 23.07.2026 | E8: 10337044 | F8: UNITED TEXTILE MILLS PRIVATE LIMITE | G8: 2 | H8: 8909490134382 | I8: 441811508002 | J8: KRTS-APWN26-GETKRTSFUT6125, OFF WHITE, L | L8: EA | M8: 1 | N8: 156 | O8: 156 | Q8: 314.7 | R8: 314.7 | S8: 2454.66 | T8: 49093.2 | U8: 5 | V8: INR | X8: =IF(ISNUMBER(VALUE(LEFT(J8,1))),LEFT(J8,MIN(IFERROR(FIND("A",UPPER(J8)),LEN(J8)+1),IFERROR(FIND("B",UPPER(J8)),LEN(J8)+1),IFERROR(FIND("C",UPPER(J8)),LEN(J8)+1),IFERROR(FIND("D",UPPER(J8)),LEN(J8)+1),IFERROR(FIND("E",UPPER(J8)),LEN(J8)+1),IFERROR(FIND("F",UPPER(J8)),LEN(J8)+1),IFERROR(FIND("G",UPPER(J8)),LEN(J8)+1),IFERROR(FIND("H",UPPER(J8)),LEN(J8)+1),IFERROR(FIND("I",UPPER(J8)),LEN(J8)+1),IFERROR(FIND("J",UPPER(J8)),LEN(J8)+1),IFERROR(FIND("K",UPPER(J8)),LEN(J8)+1),IFERROR(FIND("L",UPPER(J8)),LEN(J8)+1),IFERROR(FIND("M",UPPER(J8)),LEN(J8)+1),IFERROR(FIND("N",UPPER(J8)),LEN(J8)+1),IFERROR(FIND("O",UPPER(J8)),LEN(J8)+1),IFERROR(FIND("P",UPPER(J8)),LEN(J8)+1),IFERROR(FIND("Q",UPPER(J8)),LEN(J8)+1),IFERROR(FIND("R",UPPER(J8)),LEN(J8)+1),IFERROR(FIND("S",UPPER(J8)),LEN(J8)+1),IFERROR(FIND("T",UPPER(J8)),LEN(J8)+1),IFERROR(FIND("U",UPPER(J8)),LEN(J8)+1),IFERROR(FIND("V",UPPER(J8)),LEN(J8)+1),IFERROR(FIND("W",UPPER(J8)),LEN(J8)+1),IFERROR(FIND("X",UPPER(J8)),LEN(J8)+1),IFERROR(FIND("Y",UPPER(J8)),LEN(J8)+1),IFERROR(FIND("Z",UPPER(J8)),LEN(J8)+1))-1),LEFT(TEXT(I8,"0"),LEN(TEXT(I8,"0"))-3)) -> 441811508 | Y8: =IF(ISNUMBER(SEARCH("(RP)",J8)),"RP","DC") -> DC | Z8: =IF(ISNUMBER(SEARCH("(RP)",J8)),O8,IF(RIGHT(TRIM(J8),3)=", S",O8,0)) -> 0 | AA8: =IF(ISNUMBER(SEARCH("(RP)",J8)),O8,IF(RIGHT(TRIM(J8),3)=", M",O8,0)) -> 0 | AB8: =IF(ISNUMBER(SEARCH("(RP)",J8)),O8,IF(RIGHT(TRIM(J8),3)=", L",O8,0)) -> 156 | AC8: =IF(ISNUMBER(SEARCH("(RP)",J8)),O8,IF(RIGHT(TRIM(J8),4)=", XL",O8,0)) -> 0 | AD8: =IF(ISNUMBER(SEARCH("(RP)",J8)),O8,IF(OR(RIGHT(TRIM(J8),5)=", XXL",RIGHT(TRIM(J8),5)=", 2XL"),O8,0)) -> 0 | AE8: {=IFERROR(_xlfn.XLOOKUP(H8,Sheet1!$G:$G,Sheet1!$F:$F),IFERROR(_xlfn.XLOOKUP(1,(--($X$2:$X$1074=X8))*(--ISNUMBER(MATCH($H$2:$H$1074,Sheet1!$G:$G,0))),_xlfn.XLOOKUP($H$2:$H$1074,Sheet1!$G:$G,Sheet1!$F:$F,"")),"NOT FOUND"))} -> GETKRTSFUT6125 | AF8: =IFERROR(IF(ISNUMBER(SEARCH("(RP)",J8)),TRIM(SUBSTITUTE(MID(J8,10,LEN(J8)),"(RP)","")),TRIM(MID(J8,FIND(",",J8)+1,FIND(",",J8,FIND(",",J8)+1)-FIND(",",J8)-1))),"") -> OFF WHITE | AG8: =IF(A8="SZAF","Bangalore",IF(A8="SAEX","JHAJJAR",IF(A8="S0EU","HARIPAL",""))) -> JHAJJAR | AH8: =IF(OR(J8="",AE8="",AE8="NOT FOUND"),"",IF(Y8="RP",IFERROR(LEFT(_xlfn.XLOOKUP(AE8,Sheet1!$F:$F,Sheet1!$W:$W),FIND("-",_xlfn.XLOOKUP(AE8,Sheet1!$F:$F,Sheet1!$W:$W),FIND("-",_xlfn.XLOOKUP(AE8,Sheet1!$F:$F,Sheet1!$W:$W))+1))&AE8,"NOT FOUND"),LEFT(J8,FIND("-",J8,FIND("-",J8)+1))&AE8)) -> KRTS-APWN26-GETKRTSFUT6125
A9: SAEX | B9: 5114202422 | C9: 01.05.2026 | D9: 23.07.2026 | E9: 10337044 | F9: UNITED TEXTILE MILLS PRIVATE LIMITE | G9: 3 | H9: 8909490134399 | I9: 441811508003 | J9: KRTS-APWN26-GETKRTSFUT6125, OFF WHITE, M | L9: EA | M9: 1 | N9: 156 | O9: 156 | Q9: 314.7 | R9: 314.7 | S9: 2454.66 | T9: 49093.2 | U9: 5 | V9: INR | X9: =IF(ISNUMBER(VALUE(LEFT(J9,1))),LEFT(J9,MIN(IFERROR(FIND("A",UPPER(J9)),LEN(J9)+1),IFERROR(FIND("B",UPPER(J9)),LEN(J9)+1),IFERROR(FIND("C",UPPER(J9)),LEN(J9)+1),IFERROR(FIND("D",UPPER(J9)),LEN(J9)+1),IFERROR(FIND("E",UPPER(J9)),LEN(J9)+1),IFERROR(FIND("F",UPPER(J9)),LEN(J9)+1),IFERROR(FIND("G",UPPER(J9)),LEN(J9)+1),IFERROR(FIND("H",UPPER(J9)),LEN(J9)+1),IFERROR(FIND("I",UPPER(J9)),LEN(J9)+1),IFERROR(FIND("J",UPPER(J9)),LEN(J9)+1),IFERROR(FIND("K",UPPER(J9)),LEN(J9)+1),IFERROR(FIND("L",UPPER(J9)),LEN(J9)+1),IFERROR(FIND("M",UPPER(J9)),LEN(J9)+1),IFERROR(FIND("N",UPPER(J9)),LEN(J9)+1),IFERROR(FIND("O",UPPER(J9)),LEN(J9)+1),IFERROR(FIND("P",UPPER(J9)),LEN(J9)+1),IFERROR(FIND("Q",UPPER(J9)),LEN(J9)+1),IFERROR(FIND("R",UPPER(J9)),LEN(J9)+1),IFERROR(FIND("S",UPPER(J9)),LEN(J9)+1),IFERROR(FIND("T",UPPER(J9)),LEN(J9)+1),IFERROR(FIND("U",UPPER(J9)),LEN(J9)+1),IFERROR(FIND("V",UPPER(J9)),LEN(J9)+1),IFERROR(FIND("W",UPPER(J9)),LEN(J9)+1),IFERROR(FIND("X",UPPER(J9)),LEN(J9)+1),IFERROR(FIND("Y",UPPER(J9)),LEN(J9)+1),IFERROR(FIND("Z",UPPER(J9)),LEN(J9)+1))-1),LEFT(TEXT(I9,"0"),LEN(TEXT(I9,"0"))-3)) -> 441811508 | Y9: =IF(ISNUMBER(SEARCH("(RP)",J9)),"RP","DC") -> DC | Z9: =IF(ISNUMBER(SEARCH("(RP)",J9)),O9,IF(RIGHT(TRIM(J9),3)=", S",O9,0)) -> 0 | AA9: =IF(ISNUMBER(SEARCH("(RP)",J9)),O9,IF(RIGHT(TRIM(J9),3)=", M",O9,0)) -> 156 | AB9: =IF(ISNUMBER(SEARCH("(RP)",J9)),O9,IF(RIGHT(TRIM(J9),3)=", L",O9,0)) -> 0 | AC9: =IF(ISNUMBER(SEARCH("(RP)",J9)),O9,IF(RIGHT(TRIM(J9),4)=", XL",O9,0)) -> 0 | AD9: =IF(ISNUMBER(SEARCH("(RP)",J9)),O9,IF(OR(RIGHT(TRIM(J9),5)=", XXL",RIGHT(TRIM(J9),5)=", 2XL"),O9,0)) -> 0 | AE9: {=IFERROR(_xlfn.XLOOKUP(H9,Sheet1!$G:$G,Sheet1!$F:$F),IFERROR(_xlfn.XLOOKUP(1,(--($X$2:$X$1074=X9))*(--ISNUMBER(MATCH($H$2:$H$1074,Sheet1!$G:$G,0))),_xlfn.XLOOKUP($H$2:$H$1074,Sheet1!$G:$G,Sheet1!$F:$F,"")),"NOT FOUND"))} -> GETKRTSFUT6125 | AF9: =IFERROR(IF(ISNUMBER(SEARCH("(RP)",J9)),TRIM(SUBSTITUTE(MID(J9,10,LEN(J9)),"(RP)","")),TRIM(MID(J9,FIND(",",J9)+1,FIND(",",J9,FIND(",",J9)+1)-FIND(",",J9)-1))),"") -> OFF WHITE | AG9: =IF(A9="SZAF","Bangalore",IF(A9="SAEX","JHAJJAR",IF(A9="S0EU","HARIPAL",""))) -> JHAJJAR | AH9: =IF(OR(J9="",AE9="",AE9="NOT FOUND"),"",IF(Y9="RP",IFERROR(LEFT(_xlfn.XLOOKUP(AE9,Sheet1!$F:$F,Sheet1!$W:$W),FIND("-",_xlfn.XLOOKUP(AE9,Sheet1!$F:$F,Sheet1!$W:$W),FIND("-",_xlfn.XLOOKUP(AE9,Sheet1!$F:$F,Sheet1!$W:$W))+1))&AE9,"NOT FOUND"),LEFT(J9,FIND("-",J9,FIND("-",J9)+1))&AE9)) -> KRTS-APWN26-GETKRTSFUT6125
A10: SAEX | B10: 5114202422 | C10: 01.05.2026 | D10: 23.07.2026 | E10: 10337044 | F10: UNITED TEXTILE MILLS PRIVATE LIMITE | G10: 4 | H10: 8909490134405 | I10: 441811508004 | J10: KRTS-APWN26-GETKRTSFUT6125, OFF WHITE, S | L10: EA | M10: 1 | N10: 30 | O10: 30 | Q10: 314.7 | R10: 314.7 | S10: 472.05 | T10: 9441 | U10: 5 | V10: INR | X10: =IF(ISNUMBER(VALUE(LEFT(J10,1))),LEFT(J10,MIN(IFERROR(FIND("A",UPPER(J10)),LEN(J10)+1),IFERROR(FIND("B",UPPER(J10)),LEN(J10)+1),IFERROR(FIND("C",UPPER(J10)),LEN(J10)+1),IFERROR(FIND("D",UPPER(J10)),LEN(J10)+1),IFERROR(FIND("E",UPPER(J10)),LEN(J10)+1),IFERROR(FIND("F",UPPER(J10)),LEN(J10)+1),IFERROR(FIND("G",UPPER(J10)),LEN(J10)+1),IFERROR(FIND("H",UPPER(J10)),LEN(J10)+1),IFERROR(FIND("I",UPPER(J10)),LEN(J10)+1),IFERROR(FIND("J",UPPER(J10)),LEN(J10)+1),IFERROR(FIND("K",UPPER(J10)),LEN(J10)+1),IFERROR(FIND("L",UPPER(J10)),LEN(J10)+1),IFERROR(FIND("M",UPPER(J10)),LEN(J10)+1),IFERROR(FIND("N",UPPER(J10)),LEN(J10)+1),IFERROR(FIND("O",UPPER(J10)),LEN(J10)+1),IFERROR(FIND("P",UPPER(J10)),LEN(J10)+1),IFERROR(FIND("Q",UPPER(J10)),LEN(J10)+1),IFERROR(FIND("R",UPPER(J10)),LEN(J10)+1),IFERROR(FIND("S",UPPER(J10)),LEN(J10)+1),IFERROR(FIND("T",UPPER(J10)),LEN(J10)+1),IFERROR(FIND("U",UPPER(J10)),LEN(J10)+1),IFERROR(FIND("V",UPPER(J10)),LEN(J10)+1),IFERROR(FIND("W",UPPER(J10)),LEN(J10)+1),IFERROR(FIND("X",UPPER(J10)),LEN(J10)+1),IFERROR(FIND("Y",UPPER(J10)),LEN(J10)+1),IFERROR(FIND("Z",UPPER(J10)),LEN(J10)+1))-1),LEFT(TEXT(I10,"0"),LEN(TEXT(I10,"0"))-3)) -> 441811508 | Y10: =IF(ISNUMBER(SEARCH("(RP)",J10)),"RP","DC") -> DC | Z10: =IF(ISNUMBER(SEARCH("(RP)",J10)),O10,IF(RIGHT(TRIM(J10),3)=", S",O10,0)) -> 30 | AA10: =IF(ISNUMBER(SEARCH("(RP)",J10)),O10,IF(RIGHT(TRIM(J10),3)=", M",O10,0)) -> 0 | AB10: =IF(ISNUMBER(SEARCH("(RP)",J10)),O10,IF(RIGHT(TRIM(J10),3)=", L",O10,0)) -> 0 | AC10: =IF(ISNUMBER(SEARCH("(RP)",J10)),O10,IF(RIGHT(TRIM(J10),4)=", XL",O10,0)) -> 0 | AD10: =IF(ISNUMBER(SEARCH("(RP)",J10)),O10,IF(OR(RIGHT(TRIM(J10),5)=", XXL",RIGHT(TRIM(J10),5)=", 2XL"),O10,0)) -> 0 | AE10: {=IFERROR(_xlfn.XLOOKUP(H10,Sheet1!$G:$G,Sheet1!$F:$F),IFERROR(_xlfn.XLOOKUP(1,(--($X$2:$X$1074=X10))*(--ISNUMBER(MATCH($H$2:$H$1074,Sheet1!$G:$G,0))),_xlfn.XLOOKUP($H$2:$H$1074,Sheet1!$G:$G,Sheet1!$F:$F,"")),"NOT FOUND"))} -> GETKRTSFUT6125 | AF10: =IFERROR(IF(ISNUMBER(SEARCH("(RP)",J10)),TRIM(SUBSTITUTE(MID(J10,10,LEN(J10)),"(RP)","")),TRIM(MID(J10,FIND(",",J10)+1,FIND(",",J10,FIND(",",J10)+1)-FIND(",",J10)-1))),"") -> OFF WHITE | AG10: =IF(A10="SZAF","Bangalore",IF(A10="SAEX","JHAJJAR",IF(A10="S0EU","HARIPAL",""))) -> JHAJJAR | AH10: =IF(OR(J10="",AE10="",AE10="NOT FOUND"),"",IF(Y10="RP",IFERROR(LEFT(_xlfn.XLOOKUP(AE10,Sheet1!$F:$F,Sheet1!$W:$W),FIND("-",_xlfn.XLOOKUP(AE10,Sheet1!$F:$F,Sheet1!$W:$W),FIND("-",_xlfn.XLOOKUP(AE10,Sheet1!$F:$F,Sheet1!$W:$W))+1))&AE10,"NOT FOUND"),LEFT(J10,FIND("-",J10,FIND("-",J10)+1))&AE10)) -> KRTS-APWN26-GETKRTSFUT6125
A11: SAEX | B11: 5114202422 | C11: 01.05.2026 | D11: 23.07.2026 | E11: 10337044 | F11: UNITED TEXTILE MILLS PRIVATE LIMITE | G11: 5 | H11: 8909490134412 | I11: 441811508005 | J11: KRTS-APWN26-GETKRTSFUT612, OFF WHITE, XL | L11: EA | M11: 1 | N11: 132 | O11: 132 | Q11: 314.7 | R11: 314.7 | S11: 2077.02 | T11: 41540.4 | U11: 5 | V11: INR | X11: =IF(ISNUMBER(VALUE(LEFT(J11,1))),LEFT(J11,MIN(IFERROR(FIND("A",UPPER(J11)),LEN(J11)+1),IFERROR(FIND("B",UPPER(J11)),LEN(J11)+1),IFERROR(FIND("C",UPPER(J11)),LEN(J11)+1),IFERROR(FIND("D",UPPER(J11)),LEN(J11)+1),IFERROR(FIND("E",UPPER(J11)),LEN(J11)+1),IFERROR(FIND("F",UPPER(J11)),LEN(J11)+1),IFERROR(FIND("G",UPPER(J11)),LEN(J11)+1),IFERROR(FIND("H",UPPER(J11)),LEN(J11)+1),IFERROR(FIND("I",UPPER(J11)),LEN(J11)+1),IFERROR(FIND("J",UPPER(J11)),LEN(J11)+1),IFERROR(FIND("K",UPPER(J11)),LEN(J11)+1),IFERROR(FIND("L",UPPER(J11)),LEN(J11)+1),IFERROR(FIND("M",UPPER(J11)),LEN(J11)+1),IFERROR(FIND("N",UPPER(J11)),LEN(J11)+1),IFERROR(FIND("O",UPPER(J11)),LEN(J11)+1),IFERROR(FIND("P",UPPER(J11)),LEN(J11)+1),IFERROR(FIND("Q",UPPER(J11)),LEN(J11)+1),IFERROR(FIND("R",UPPER(J11)),LEN(J11)+1),IFERROR(FIND("S",UPPER(J11)),LEN(J11)+1),IFERROR(FIND("T",UPPER(J11)),LEN(J11)+1),IFERROR(FIND("U",UPPER(J11)),LEN(J11)+1),IFERROR(FIND("V",UPPER(J11)),LEN(J11)+1),IFERROR(FIND("W",UPPER(J11)),LEN(J11)+1),IFERROR(FIND("X",UPPER(J11)),LEN(J11)+1),IFERROR(FIND("Y",UPPER(J11)),LEN(J11)+1),IFERROR(FIND("Z",UPPER(J11)),LEN(J11)+1))-1),LEFT(TEXT(I11,"0"),LEN(TEXT(I11,"0"))-3)) -> 441811508 | Y11: =IF(ISNUMBER(SEARCH("(RP)",J11)),"RP","DC") -> DC | Z11: =IF(ISNUMBER(SEARCH("(RP)",J11)),O11,IF(RIGHT(TRIM(J11),3)=", S",O11,0)) -> 0 | AA11: =IF(ISNUMBER(SEARCH("(RP)",J11)),O11,IF(RIGHT(TRIM(J11),3)=", M",O11,0)) -> 0 | AB11: =IF(ISNUMBER(SEARCH("(RP)",J11)),O11,IF(RIGHT(TRIM(J11),3)=", L",O11,0)) -> 0 | AC11: =IF(ISNUMBER(SEARCH("(RP)",J11)),O11,IF(RIGHT(TRIM(J11),4)=", XL",O11,0)) -> 132 | AD11: =IF(ISNUMBER(SEARCH("(RP)",J11)),O11,IF(OR(RIGHT(TRIM(J11),5)=", XXL",RIGHT(TRIM(J11),5)=", 2XL"),O11,0)) -> 0 | AE11: {=IFERROR(_xlfn.XLOOKUP(H11,Sheet1!$G:$G,Sheet1!$F:$F),IFERROR(_xlfn.XLOOKUP(1,(--($X$2:$X$1074=X11))*(--ISNUMBER(MATCH($H$2:$H$1074,Sheet1!$G:$G,0))),_xlfn.XLOOKUP($H$2:$H$1074,Sheet1!$G:$G,Sheet1!$F:$F,"")),"NOT FOUND"))} -> GETKRTSFUT6125 | AF11: =IFERROR(IF(ISNUMBER(SEARCH("(RP)",J11)),TRIM(SUBSTITUTE(MID(J11,10,LEN(J11)),"(RP)","")),TRIM(MID(J11,FIND(",",J11)+1,FIND(",",J11,FIND(",",J11)+1)-FIND(",",J11)-1))),"") -> OFF WHITE | AG11: =IF(A11="SZAF","Bangalore",IF(A11="SAEX","JHAJJAR",IF(A11="S0EU","HARIPAL",""))) -> JHAJJAR | AH11: =IF(OR(J11="",AE11="",AE11="NOT FOUND"),"",IF(Y11="RP",IFERROR(LEFT(_xlfn.XLOOKUP(AE11,Sheet1!$F:$F,Sheet1!$W:$W),FIND("-",_xlfn.XLOOKUP(AE11,Sheet1!$F:$F,Sheet1!$W:$W),FIND("-",_xlfn.XLOOKUP(AE11,Sheet1!$F:$F,Sheet1!$W:$W))+1))&AE11,"NOT FOUND"),LEFT(J11,FIND("-",J11,FIND("-",J11)+1))&AE11)) -> KRTS-APWN26-GETKRTSFUT6125
A12: S0EU | B12: 5114202420 | C12: 01.05.2026 | D12: 23.07.2026 | E12: 10337044 | F12: UNITED TEXTILE MILLS PRIVATE LIMITE | G12: 1 | H12: 8909490134375 | I12: 441811508001 | J12: KRTS-APWN26-GETKRTSFUT61, OFF WHITE, 2XL | L12: EA | M12: 1 | N12: 30 | O12: 30 | Q12: 314.7 | R12: 314.7 | S12: 472.05 | T12: 9441 | U12: 5 | V12: INR | X12: =IF(ISNUMBER(VALUE(LEFT(J12,1))),LEFT(J12,MIN(IFERROR(FIND("A",UPPER(J12)),LEN(J12)+1),IFERROR(FIND("B",UPPER(J12)),LEN(J12)+1),IFERROR(FIND("C",UPPER(J12)),LEN(J12)+1),IFERROR(FIND("D",UPPER(J12)),LEN(J12)+1),IFERROR(FIND("E",UPPER(J12)),LEN(J12)+1),IFERROR(FIND("F",UPPER(J12)),LEN(J12)+1),IFERROR(FIND("G",UPPER(J12)),LEN(J12)+1),IFERROR(FIND("H",UPPER(J12)),LEN(J12)+1),IFERROR(FIND("I",UPPER(J12)),LEN(J12)+1),IFERROR(FIND("J",UPPER(J12)),LEN(J12)+1),IFERROR(FIND("K",UPPER(J12)),LEN(J12)+1),IFERROR(FIND("L",UPPER(J12)),LEN(J12)+1),IFERROR(FIND("M",UPPER(J12)),LEN(J12)+1),IFERROR(FIND("N",UPPER(J12)),LEN(J12)+1),IFERROR(FIND("O",UPPER(J12)),LEN(J12)+1),IFERROR(FIND("P",UPPER(J12)),LEN(J12)+1),IFERROR(FIND("Q",UPPER(J12)),LEN(J12)+1),IFERROR(FIND("R",UPPER(J12)),LEN(J12)+1),IFERROR(FIND("S",UPPER(J12)),LEN(J12)+1),IFERROR(FIND("T",UPPER(J12)),LEN(J12)+1),IFERROR(FIND("U",UPPER(J12)),LEN(J12)+1),IFERROR(FIND("V",UPPER(J12)),LEN(J12)+1),IFERROR(FIND("W",UPPER(J12)),LEN(J12)+1),IFERROR(FIND("X",UPPER(J12)),LEN(J12)+1),IFERROR(FIND("Y",UPPER(J12)),LEN(J12)+1),IFERROR(FIND("Z",UPPER(J12)),LEN(J12)+1))-1),LEFT(TEXT(I12,"0"),LEN(TEXT(I12,"0"))-3)) -> 441811508 | Y12: =IF(ISNUMBER(SEARCH("(RP)",J12)),"RP","DC") -> DC | Z12: =IF(ISNUMBER(SEARCH("(RP)",J12)),O12,IF(RIGHT(TRIM(J12),3)=", S",O12,0)) -> 0 | AA12: =IF(ISNUMBER(SEARCH("(RP)",J12)),O12,IF(RIGHT(TRIM(J12),3)=", M",O12,0)) -> 0 | AB12: =IF(ISNUMBER(SEARCH("(RP)",J12)),O12,IF(RIGHT(TRIM(J12),3)=", L",O12,0)) -> 0 | AC12: =IF(ISNUMBER(SEARCH("(RP)",J12)),O12,IF(RIGHT(TRIM(J12),4)=", XL",O12,0)) -> 0 | AD12: =IF(ISNUMBER(SEARCH("(RP)",J12)),O12,IF(OR(RIGHT(TRIM(J12),5)=", XXL",RIGHT(TRIM(J12),5)=", 2XL"),O12,0)) -> 30 | AE12: {=IFERROR(_xlfn.XLOOKUP(H12,Sheet1!$G:$G,Sheet1!$F:$F),IFERROR(_xlfn.XLOOKUP(1,(--($X$2:$X$1074=X12))*(--ISNUMBER(MATCH($H$2:$H$1074,Sheet1!$G:$G,0))),_xlfn.XLOOKUP($H$2:$H$1074,Sheet1!$G:$G,Sheet1!$F:$F,"")),"NOT FOUND"))} -> GETKRTSFUT6125 | AF12: =IFERROR(IF(ISNUMBER(SEARCH("(RP)",J12)),TRIM(SUBSTITUTE(MID(J12,10,LEN(J12)),"(RP)","")),TRIM(MID(J12,FIND(",",J12)+1,FIND(",",J12,FIND(",",J12)+1)-FIND(",",J12)-1))),"") -> OFF WHITE | AG12: =IF(A12="SZAF","Bangalore",IF(A12="SAEX","JHAJJAR",IF(A12="S0EU","HARIPAL",""))) -> HARIPAL | AH12: =IF(OR(J12="",AE12="",AE12="NOT FOUND"),"",IF(Y12="RP",IFERROR(LEFT(_xlfn.XLOOKUP(AE12,Sheet1!$F:$F,Sheet1!$W:$W),FIND("-",_xlfn.XLOOKUP(AE12,Sheet1!$F:$F,Sheet1!$W:$W),FIND("-",_xlfn.XLOOKUP(AE12,Sheet1!$F:$F,Sheet1!$W:$W))+1))&AE12,"NOT FOUND"),LEFT(J12,FIND("-",J12,FIND("-",J12)+1))&AE12)) -> KRTS-APWN26-GETKRTSFUT6125
A13: S0EU | B13: 5114202420 | C13: 01.05.2026 | D13: 23.07.2026 | E13: 10337044 | F13: UNITED TEXTILE MILLS PRIVATE LIMITE | G13: 2 | H13: 8909490134382 | I13: 441811508002 | J13: KRTS-APWN26-GETKRTSFUT6125, OFF WHITE, L | L13: EA | M13: 1 | N13: 186 | O13: 186 | Q13: 314.7 | R13: 314.7 | S13: 2926.71 | T13: 58534.2 | U13: 5 | V13: INR | X13: =IF(ISNUMBER(VALUE(LEFT(J13,1))),LEFT(J13,MIN(IFERROR(FIND("A",UPPER(J13)),LEN(J13)+1),IFERROR(FIND("B",UPPER(J13)),LEN(J13)+1),IFERROR(FIND("C",UPPER(J13)),LEN(J13)+1),IFERROR(FIND("D",UPPER(J13)),LEN(J13)+1),IFERROR(FIND("E",UPPER(J13)),LEN(J13)+1),IFERROR(FIND("F",UPPER(J13)),LEN(J13)+1),IFERROR(FIND("G",UPPER(J13)),LEN(J13)+1),IFERROR(FIND("H",UPPER(J13)),LEN(J13)+1),IFERROR(FIND("I",UPPER(J13)),LEN(J13)+1),IFERROR(FIND("J",UPPER(J13)),LEN(J13)+1),IFERROR(FIND("K",UPPER(J13)),LEN(J13)+1),IFERROR(FIND("L",UPPER(J13)),LEN(J13)+1),IFERROR(FIND("M",UPPER(J13)),LEN(J13)+1),IFERROR(FIND("N",UPPER(J13)),LEN(J13)+1),IFERROR(FIND("O",UPPER(J13)),LEN(J13)+1),IFERROR(FIND("P",UPPER(J13)),LEN(J13)+1),IFERROR(FIND("Q",UPPER(J13)),LEN(J13)+1),IFERROR(FIND("R",UPPER(J13)),LEN(J13)+1),IFERROR(FIND("S",UPPER(J13)),LEN(J13)+1),IFERROR(FIND("T",UPPER(J13)),LEN(J13)+1),IFERROR(FIND("U",UPPER(J13)),LEN(J13)+1),IFERROR(FIND("V",UPPER(J13)),LEN(J13)+1),IFERROR(FIND("W",UPPER(J13)),LEN(J13)+1),IFERROR(FIND("X",UPPER(J13)),LEN(J13)+1),IFERROR(FIND("Y",UPPER(J13)),LEN(J13)+1),IFERROR(FIND("Z",UPPER(J13)),LEN(J13)+1))-1),LEFT(TEXT(I13,"0"),LEN(TEXT(I13,"0"))-3)) -> 441811508 | Y13: =IF(ISNUMBER(SEARCH("(RP)",J13)),"RP","DC") -> DC | Z13: =IF(ISNUMBER(SEARCH("(RP)",J13)),O13,IF(RIGHT(TRIM(J13),3)=", S",O13,0)) -> 0 | AA13: =IF(ISNUMBER(SEARCH("(RP)",J13)),O13,IF(RIGHT(TRIM(J13),3)=", M",O13,0)) -> 0 | AB13: =IF(ISNUMBER(SEARCH("(RP)",J13)),O13,IF(RIGHT(TRIM(J13),3)=", L",O13,0)) -> 186 | AC13: =IF(ISNUMBER(SEARCH("(RP)",J13)),O13,IF(RIGHT(TRIM(J13),4)=", XL",O13,0)) -> 0 | AD13: =IF(ISNUMBER(SEARCH("(RP)",J13)),O13,IF(OR(RIGHT(TRIM(J13),5)=", XXL",RIGHT(TRIM(J13),5)=", 2XL"),O13,0)) -> 0 | AE13: {=IFERROR(_xlfn.XLOOKUP(H13,Sheet1!$G:$G,Sheet1!$F:$F),IFERROR(_xlfn.XLOOKUP(1,(--($X$2:$X$1074=X13))*(--ISNUMBER(MATCH($H$2:$H$1074,Sheet1!$G:$G,0))),_xlfn.XLOOKUP($H$2:$H$1074,Sheet1!$G:$G,Sheet1!$F:$F,"")),"NOT FOUND"))} -> GETKRTSFUT6125 | AF13: =IFERROR(IF(ISNUMBER(SEARCH("(RP)",J13)),TRIM(SUBSTITUTE(MID(J13,10,LEN(J13)),"(RP)","")),TRIM(MID(J13,FIND(",",J13)+1,FIND(",",J13,FIND(",",J13)+1)-FIND(",",J13)-1))),"") -> OFF WHITE | AG13: =IF(A13="SZAF","Bangalore",IF(A13="SAEX","JHAJJAR",IF(A13="S0EU","HARIPAL",""))) -> HARIPAL | AH13: =IF(OR(J13="",AE13="",AE13="NOT FOUND"),"",IF(Y13="RP",IFERROR(LEFT(_xlfn.XLOOKUP(AE13,Sheet1!$F:$F,Sheet1!$W:$W),FIND("-",_xlfn.XLOOKUP(AE13,Sheet1!$F:$F,Sheet1!$W:$W),FIND("-",_xlfn.XLOOKUP(AE13,Sheet1!$F:$F,Sheet1!$W:$W))+1))&AE13,"NOT FOUND"),LEFT(J13,FIND("-",J13,FIND("-",J13)+1))&AE13)) -> KRTS-APWN26-GETKRTSFUT6125
A14: S0EU | B14: 5114202420 | C14: 01.05.2026 | D14: 23.07.2026 | E14: 10337044 | F14: UNITED TEXTILE MILLS PRIVATE LIMITE | G14: 3 | H14: 8909490134399 | I14: 441811508003 | J14: KRTS-APWN26-GETKRTSFUT6125, OFF WHITE, M | L14: EA | M14: 1 | N14: 186 | O14: 186 | Q14: 314.7 | R14: 314.7 | S14: 2926.71 | T14: 58534.2 | U14: 5 | V14: INR | X14: =IF(ISNUMBER(VALUE(LEFT(J14,1))),LEFT(J14,MIN(IFERROR(FIND("A",UPPER(J14)),LEN(J14)+1),IFERROR(FIND("B",UPPER(J14)),LEN(J14)+1),IFERROR(FIND("C",UPPER(J14)),LEN(J14)+1),IFERROR(FIND("D",UPPER(J14)),LEN(J14)+1),IFERROR(FIND("E",UPPER(J14)),LEN(J14)+1),IFERROR(FIND("F",UPPER(J14)),LEN(J14)+1),IFERROR(FIND("G",UPPER(J14)),LEN(J14)+1),IFERROR(FIND("H",UPPER(J14)),LEN(J14)+1),IFERROR(FIND("I",UPPER(J14)),LEN(J14)+1),IFERROR(FIND("J",UPPER(J14)),LEN(J14)+1),IFERROR(FIND("K",UPPER(J14)),LEN(J14)+1),IFERROR(FIND("L",UPPER(J14)),LEN(J14)+1),IFERROR(FIND("M",UPPER(J14)),LEN(J14)+1),IFERROR(FIND("N",UPPER(J14)),LEN(J14)+1),IFERROR(FIND("O",UPPER(J14)),LEN(J14)+1),IFERROR(FIND("P",UPPER(J14)),LEN(J14)+1),IFERROR(FIND("Q",UPPER(J14)),LEN(J14)+1),IFERROR(FIND("R",UPPER(J14)),LEN(J14)+1),IFERROR(FIND("S",UPPER(J14)),LEN(J14)+1),IFERROR(FIND("T",UPPER(J14)),LEN(J14)+1),IFERROR(FIND("U",UPPER(J14)),LEN(J14)+1),IFERROR(FIND("V",UPPER(J14)),LEN(J14)+1),IFERROR(FIND("W",UPPER(J14)),LEN(J14)+1),IFERROR(FIND("X",UPPER(J14)),LEN(J14)+1),IFERROR(FIND("Y",UPPER(J14)),LEN(J14)+1),IFERROR(FIND("Z",UPPER(J14)),LEN(J14)+1))-1),LEFT(TEXT(I14,"0"),LEN(TEXT(I14,"0"))-3)) -> 441811508 | Y14: =IF(ISNUMBER(SEARCH("(RP)",J14)),"RP","DC") -> DC | Z14: =IF(ISNUMBER(SEARCH("(RP)",J14)),O14,IF(RIGHT(TRIM(J14),3)=", S",O14,0)) -> 0 | AA14: =IF(ISNUMBER(SEARCH("(RP)",J14)),O14,IF(RIGHT(TRIM(J14),3)=", M",O14,0)) -> 186 | AB14: =IF(ISNUMBER(SEARCH("(RP)",J14)),O14,IF(RIGHT(TRIM(J14),3)=", L",O14,0)) -> 0 | AC14: =IF(ISNUMBER(SEARCH("(RP)",J14)),O14,IF(RIGHT(TRIM(J14),4)=", XL",O14,0)) -> 0 | AD14: =IF(ISNUMBER(SEARCH("(RP)",J14)),O14,IF(OR(RIGHT(TRIM(J14),5)=", XXL",RIGHT(TRIM(J14),5)=", 2XL"),O14,0)) -> 0 | AE14: {=IFERROR(_xlfn.XLOOKUP(H14,Sheet1!$G:$G,Sheet1!$F:$F),IFERROR(_xlfn.XLOOKUP(1,(--($X$2:$X$1074=X14))*(--ISNUMBER(MATCH($H$2:$H$1074,Sheet1!$G:$G,0))),_xlfn.XLOOKUP($H$2:$H$1074,Sheet1!$G:$G,Sheet1!$F:$F,"")),"NOT FOUND"))} -> GETKRTSFUT6125 | AF14: =IFERROR(IF(ISNUMBER(SEARCH("(RP)",J14)),TRIM(SUBSTITUTE(MID(J14,10,LEN(J14)),"(RP)","")),TRIM(MID(J14,FIND(",",J14)+1,FIND(",",J14,FIND(",",J14)+1)-FIND(",",J14)-1))),"") -> OFF WHITE | AG14: =IF(A14="SZAF","Bangalore",IF(A14="SAEX","JHAJJAR",IF(A14="S0EU","HARIPAL",""))) -> HARIPAL | AH14: =IF(OR(J14="",AE14="",AE14="NOT FOUND"),"",IF(Y14="RP",IFERROR(LEFT(_xlfn.XLOOKUP(AE14,Sheet1!$F:$F,Sheet1!$W:$W),FIND("-",_xlfn.XLOOKUP(AE14,Sheet1!$F:$F,Sheet1!$W:$W),FIND("-",_xlfn.XLOOKUP(AE14,Sheet1!$F:$F,Sheet1!$W:$W))+1))&AE14,"NOT FOUND"),LEFT(J14,FIND("-",J14,FIND("-",J14)+1))&AE14)) -> KRTS-APWN26-GETKRTSFUT6125
... A636: SZAF | B636: 5112963769 | C636: 30.01.2026 | D636: 30.06.2026 | E636: 10337044 | F636: UNITED TEXTILE MILLS PRIVATE LIMITE | G636: 5 | H636: 8909103992484 | I636: 441857089014 | J636: KRTS-APSU26-YETKRTSCUT5008, RUST, M | L636: EA | M636: 1 | N636: 566 | O636: 566 | Q636: 0 | R636: 0 | S636: 0 | T636: 0 | U636: 0 | V636: INR | X636: =IF(ISNUMBER(VALUE(LEFT(J636,1))),LEFT(J636,MIN(IFERROR(FIND("A",UPPER(J636)),LEN(J636)+1),IFERROR(FIND("B",UPPER(J636)),LEN(J636)+1),IFERROR(FIND("C",UPPER(J636)),LEN(J636)+1),IFERROR(FIND("D",UPPER(J636)),LEN(J636)+1),IFERROR(FIND("E",UPPER(J636)),LEN(J636)+1),IFERROR(FIND("F",UPPER(J636)),LEN(J636)+1),IFERROR(FIND("G",UPPER(J636)),LEN(J636)+1),IFERROR(FIND("H",UPPER(J636)),LEN(J636)+1),IFERROR(FIND("I",UPPER(J636)),LEN(J636)+1),IFERROR(FIND("J",UPPER(J636)),LEN(J636)+1),IFERROR(FIND("K",UPPER(J636)),LEN(J636)+1),IFERROR(FIND("L",UPPER(J636)),LEN(J636)+1),IFERROR(FIND("M",UPPER(J636)),LEN(J636)+1),IFERROR(FIND("N",UPPER(J636)),LEN(J636)+1),IFERROR(FIND("O",UPPER(J636)),LEN(J636)+1),IFERROR(FIND("P",UPPER(J636)),LEN(J636)+1),IFERROR(FIND("Q",UPPER(J636)),LEN(J636)+1),IFERROR(FIND("R",UPPER(J636)),LEN(J636)+1),IFERROR(FIND("S",UPPER(J636)),LEN(J636)+1),IFERROR(FIND("T",UPPER(J636)),LEN(J636)+1),IFERROR(FIND("U",UPPER(J636)),LEN(J636)+1),IFERROR(FIND("V",UPPER(J636)),LEN(J636)+1),IFERROR(FIND("W",UPPER(J636)),LEN(J636)+1),IFERROR(FIND("X",UPPER(J636)),LEN(J636)+1),IFERROR(FIND("Y",UPPER(J636)),LEN(J636)+1),IFERROR(FIND("Z",UPPER(J636)),LEN(J636)+1))-1),LEFT(TEXT(I636,"0"),LEN(TEXT(I636,"0"))-3)) -> 441857089 | Y636: =IF(ISNUMBER(SEARCH("(RP)",J636)),"RP","DC") -> DC | Z636: =IF(ISNUMBER(SEARCH("(RP)",J636)),O636,IF(RIGHT(TRIM(J636),3)=", S",O636,0)) -> 0 | AA636: =IF(ISNUMBER(SEARCH("(RP)",J636)),O636,IF(RIGHT(TRIM(J636),3)=", M",O636,0)) -> 566 | AB636: =IF(ISNUMBER(SEARCH("(RP)",J636)),O636,IF(RIGHT(TRIM(J636),3)=", L",O636,0)) -> 0 | AC636: =IF(ISNUMBER(SEARCH("(RP)",J636)),O636,IF(RIGHT(TRIM(J636),4)=", XL",O636,0)) -> 0 | AD636: =IF(ISNUMBER(SEARCH("(RP)",J636)),O636,IF(OR(RIGHT(TRIM(J636),5)=", XXL",RIGHT(TRIM(J636),5)=", 2XL"),O636,0)) -> 0 | AE636: {=IFERROR(_xlfn.XLOOKUP(H636,Sheet1!$G:$G,Sheet1!$F:$F),IFERROR(_xlfn.XLOOKUP(1,(--($X$2:$X$1074=X636))*(--ISNUMBER(MATCH($H$2:$H$1074,Sheet1!$G:$G,0))),_xlfn.XLOOKUP($H$2:$H$1074,Sheet1!$G:$G,Sheet1!$F:$F,"")),"NOT FOUND"))} -> YETKRTSCUT5008 | AF636: =IFERROR(IF(ISNUMBER(SEARCH("(RP)",J636)),TRIM(SUBSTITUTE(MID(J636,10,LEN(J636)),"(RP)","")),TRIM(MID(J636,FIND(",",J636)+1,FIND(",",J636,FIND(",",J636)+1)-FIND(",",J636)-1))),"") -> RUST | AG636: =IF(A636="SZAF","Bangalore",IF(A636="SAEX","JHAJJAR",IF(A636="S0EU","HARIPAL",""))) -> Bangalore | AH636: =IF(OR(J636="",AE636="",AE636="NOT FOUND"),"",IF(Y636="RP",IFERROR(LEFT(_xlfn.XLOOKUP(AE636,Sheet1!$F:$F,Sheet1!$W:$W),FIND("-",_xlfn.XLOOKUP(AE636,Sheet1!$F:$F,Sheet1!$W:$W),FIND("-",_xlfn.XLOOKUP(AE636,Sheet1!$F:$F,Sheet1!$W:$W))+1))&AE636,"NOT FOUND"),LEFT(J636,FIND("-",J636,FIND("-",J636)+1))&AE636)) -> KRTS-APSU26-YETKRTSCUT5008
A637: SZAF | B637: 5112963769 | C637: 30.01.2026 | D637: 30.06.2026 | E637: 10337044 | F637: UNITED TEXTILE MILLS PRIVATE LIMITE | G637: 6 | H637: 8909103992477 | I637: 441857089015 | J637: KRTS-APSU26-YETKRTSCUT5008, RUST, S | L637: EA | M637: 1 | N637: 566 | O637: 566 | Q637: 0 | R637: 0 | S637: 0 | T637: 0 | U637: 0 | X637: =IF(ISNUMBER(VALUE(LEFT(J637,1))),LEFT(J637,MIN(IFERROR(FIND("A",UPPER(J637)),LEN(J637)+1),IFERROR(FIND("B",UPPER(J637)),LEN(J637)+1),IFERROR(FIND("C",UPPER(J637)),LEN(J637)+1),IFERROR(FIND("D",UPPER(J637)),LEN(J637)+1),IFERROR(FIND("E",UPPER(J637)),LEN(J637)+1),IFERROR(FIND("F",UPPER(J637)),LEN(J637)+1),IFERROR(FIND("G",UPPER(J637)),LEN(J637)+1),IFERROR(FIND("H",UPPER(J637)),LEN(J637)+1),IFERROR(FIND("I",UPPER(J637)),LEN(J637)+1),IFERROR(FIND("J",UPPER(J637)),LEN(J637)+1),IFERROR(FIND("K",UPPER(J637)),LEN(J637)+1),IFERROR(FIND("L",UPPER(J637)),LEN(J637)+1),IFERROR(FIND("M",UPPER(J637)),LEN(J637)+1),IFERROR(FIND("N",UPPER(J637)),LEN(J637)+1),IFERROR(FIND("O",UPPER(J637)),LEN(J637)+1),IFERROR(FIND("P",UPPER(J637)),LEN(J637)+1),IFERROR(FIND("Q",UPPER(J637)),LEN(J637)+1),IFERROR(FIND("R",UPPER(J637)),LEN(J637)+1),IFERROR(FIND("S",UPPER(J637)),LEN(J637)+1),IFERROR(FIND("T",UPPER(J637)),LEN(J637)+1),IFERROR(FIND("U",UPPER(J637)),LEN(J637)+1),IFERROR(FIND("V",UPPER(J637)),LEN(J637)+1),IFERROR(FIND("W",UPPER(J637)),LEN(J637)+1),IFERROR(FIND("X",UPPER(J637)),LEN(J637)+1),IFERROR(FIND("Y",UPPER(J637)),LEN(J637)+1),IFERROR(FIND("Z",UPPER(J637)),LEN(J637)+1))-1),LEFT(TEXT(I637,"0"),LEN(TEXT(I637,"0"))-3)) -> 441857089 | Y637: =IF(ISNUMBER(SEARCH("(RP)",J637)),"RP","DC") -> DC | Z637: =IF(ISNUMBER(SEARCH("(RP)",J637)),O637,IF(RIGHT(TRIM(J637),3)=", S",O637,0)) -> 566 | AA637: =IF(ISNUMBER(SEARCH("(RP)",J637)),O637,IF(RIGHT(TRIM(J637),3)=", M",O637,0)) -> 0 | AB637: =IF(ISNUMBER(SEARCH("(RP)",J637)),O637,IF(RIGHT(TRIM(J637),3)=", L",O637,0)) -> 0 | AC637: =IF(ISNUMBER(SEARCH("(RP)",J637)),O637,IF(RIGHT(TRIM(J637),4)=", XL",O637,0)) -> 0 | AD637: =IF(ISNUMBER(SEARCH("(RP)",J637)),O637,IF(OR(RIGHT(TRIM(J637),5)=", XXL",RIGHT(TRIM(J637),5)=", 2XL"),O637,0)) -> 0 | AE637: {=IFERROR(_xlfn.XLOOKUP(H637,Sheet1!$G:$G,Sheet1!$F:$F),IFERROR(_xlfn.XLOOKUP(1,(--($X$2:$X$1074=X637))*(--ISNUMBER(MATCH($H$2:$H$1074,Sheet1!$G:$G,0))),_xlfn.XLOOKUP($H$2:$H$1074,Sheet1!$G:$G,Sheet1!$F:$F,"")),"NOT FOUND"))} -> YETKRTSCUT5008 | AF637: =IFERROR(IF(ISNUMBER(SEARCH("(RP)",J637)),TRIM(SUBSTITUTE(MID(J637,10,LEN(J637)),"(RP)","")),TRIM(MID(J637,FIND(",",J637)+1,FIND(",",J637,FIND(",",J637)+1)-FIND(",",J637)-1))),"") -> RUST | AG637: =IF(A637="SZAF","Bangalore",IF(A637="SAEX","JHAJJAR",IF(A637="S0EU","HARIPAL",""))) -> Bangalore | AH637: =IF(OR(J637="",AE637="",AE637="NOT FOUND"),"",IF(Y637="RP",IFERROR(LEFT(_xlfn.XLOOKUP(AE637,Sheet1!$F:$F,Sheet1!$W:$W),FIND("-",_xlfn.XLOOKUP(AE637,Sheet1!$F:$F,Sheet1!$W:$W),FIND("-",_xlfn.XLOOKUP(AE637,Sheet1!$F:$F,Sheet1!$W:$W))+1))&AE637,"NOT FOUND"),LEFT(J637,FIND("-",J637,FIND("-",J637)+1))&AE637)) -> KRTS-APSU26-YETKRTSCUT5008
A638: SZAF | B638: 5112963768 | C638: 30.01.2026 | D638: 30.06.2026 | E638: 10337044 | F638: UNITED TEXTILE MILLS PRIVATE LIMITE | G638: 1 | H638: 8909103992590 | I638: 494758188 | J638: 441857089 OFF WHITE(RP) | L638: EA | M638: 1 | N638: 566 | O638: 566 | Q638: 1221.5 | R638: 1221.5 | S638: 34568.45 | T638: 691369 | U638: 5 | V638: INR | X638: =IF(ISNUMBER(VALUE(LEFT(J638,1))),LEFT(J638,MIN(IFERROR(FIND("A",UPPER(J638)),LEN(J638)+1),IFERROR(FIND("B",UPPER(J638)),LEN(J638)+1),IFERROR(FIND("C",UPPER(J638)),LEN(J638)+1),IFERROR(FIND("D",UPPER(J638)),LEN(J638)+1),IFERROR(FIND("E",UPPER(J638)),LEN(J638)+1),IFERROR(FIND("F",UPPER(J638)),LEN(J638)+1),IFERROR(FIND("G",UPPER(J638)),LEN(J638)+1),IFERROR(FIND("H",UPPER(J638)),LEN(J638)+1),IFERROR(FIND("I",UPPER(J638)),LEN(J638)+1),IFERROR(FIND("J",UPPER(J638)),LEN(J638)+1),IFERROR(FIND("K",UPPER(J638)),LEN(J638)+1),IFERROR(FIND("L",UPPER(J638)),LEN(J638)+1),IFERROR(FIND("M",UPPER(J638)),LEN(J638)+1),IFERROR(FIND("N",UPPER(J638)),LEN(J638)+1),IFERROR(FIND("O",UPPER(J638)),LEN(J638)+1),IFERROR(FIND("P",UPPER(J638)),LEN(J638)+1),IFERROR(FIND("Q",UPPER(J638)),LEN(J638)+1),IFERROR(FIND("R",UPPER(J638)),LEN(J638)+1),IFERROR(FIND("S",UPPER(J638)),LEN(J638)+1),IFERROR(FIND("T",UPPER(J638)),LEN(J638)+1),IFERROR(FIND("U",UPPER(J638)),LEN(J638)+1),IFERROR(FIND("V",UPPER(J638)),LEN(J638)+1),IFERROR(FIND("W",UPPER(J638)),LEN(J638)+1),IFERROR(FIND("X",UPPER(J638)),LEN(J638)+1),IFERROR(FIND("Y",UPPER(J638)),LEN(J638)+1),IFERROR(FIND("Z",UPPER(J638)),LEN(J638)+1))-1),LEFT(TEXT(I638,"0"),LEN(TEXT(I638,"0"))-3)) -> 441857089 | Y638: =IF(ISNUMBER(SEARCH("(RP)",J638)),"RP","DC") -> RP | Z638: =IF(ISNUMBER(SEARCH("(RP)",J638)),O638,IF(RIGHT(TRIM(J638),3)=", S",O638,0)) -> 566 | AA638: =IF(ISNUMBER(SEARCH("(RP)",J638)),O638,IF(RIGHT(TRIM(J638),3)=", M",O638,0)) -> 566 | AB638: =IF(ISNUMBER(SEARCH("(RP)",J638)),O638,IF(RIGHT(TRIM(J638),3)=", L",O638,0)) -> 566 | AC638: =IF(ISNUMBER(SEARCH("(RP)",J638)),O638,IF(RIGHT(TRIM(J638),4)=", XL",O638,0)) -> 566 | AD638: =IF(ISNUMBER(SEARCH("(RP)",J638)),O638,IF(OR(RIGHT(TRIM(J638),5)=", XXL",RIGHT(TRIM(J638),5)=", 2XL"),O638,0)) -> 566 | AE638: {=IFERROR(_xlfn.XLOOKUP(H638,Sheet1!$G:$G,Sheet1!$F:$F),IFERROR(_xlfn.XLOOKUP(1,(--($X$2:$X$1074=X638))*(--ISNUMBER(MATCH($H$2:$H$1074,Sheet1!$G:$G,0))),_xlfn.XLOOKUP($H$2:$H$1074,Sheet1!$G:$G,Sheet1!$F:$F,"")),"NOT FOUND"))} -> YETKRTSCUT5008 | AF638: =IFERROR(IF(ISNUMBER(SEARCH("(RP)",J638)),TRIM(SUBSTITUTE(MID(J638,10,LEN(J638)),"(RP)","")),TRIM(MID(J638,FIND(",",J638)+1,FIND(",",J638,FIND(",",J638)+1)-FIND(",",J638)-1))),"") -> OFF WHITE | AG638: =IF(A638="SZAF","Bangalore",IF(A638="SAEX","JHAJJAR",IF(A638="S0EU","HARIPAL",""))) -> Bangalore | AH638: =IF(OR(J638="",AE638="",AE638="NOT FOUND"),"",IF(Y638="RP",IFERROR(LEFT(_xlfn.XLOOKUP(AE638,Sheet1!$F:$F,Sheet1!$W:$W),FIND("-",_xlfn.XLOOKUP(AE638,Sheet1!$F:$F,Sheet1!$W:$W),FIND("-",_xlfn.XLOOKUP(AE638,Sheet1!$F:$F,Sheet1!$W:$W))+1))&AE638,"NOT FOUND"),LEFT(J638,FIND("-",J638,FIND("-",J638)+1))&AE638)) -> KRTS-APSU26-YETKRTSCUT5008
A639: SZAF | B639: 5112963768 | C639: 30.01.2026 | D639: 30.06.2026 | E639: 10337044 | F639: UNITED TEXTILE MILLS PRIVATE LIMITE | G639: 2 | H639: 8909103992460 | I639: 441857089016 | J639: KRTS-APSU26-YETKRTSCUT50, OFF WHITE, 2XL | L639: EA | M639: 1 | N639: 566 | O639: 566 | Q639: 0 | R639: 0 | S639: 0 | T639: 0 | U639: 0 | V639: INR | X639: =IF(ISNUMBER(VALUE(LEFT(J639,1))),LEFT(J639,MIN(IFERROR(FIND("A",UPPER(J639)),LEN(J639)+1),IFERROR(FIND("B",UPPER(J639)),LEN(J639)+1),IFERROR(FIND("C",UPPER(J639)),LEN(J639)+1),IFERROR(FIND("D",UPPER(J639)),LEN(J639)+1),IFERROR(FIND("E",UPPER(J639)),LEN(J639)+1),IFERROR(FIND("F",UPPER(J639)),LEN(J639)+1),IFERROR(FIND("G",UPPER(J639)),LEN(J639)+1),IFERROR(FIND("H",UPPER(J639)),LEN(J639)+1),IFERROR(FIND("I",UPPER(J639)),LEN(J639)+1),IFERROR(FIND("J",UPPER(J639)),LEN(J639)+1),IFERROR(FIND("K",UPPER(J639)),LEN(J639)+1),IFERROR(FIND("L",UPPER(J639)),LEN(J639)+1),IFERROR(FIND("M",UPPER(J639)),LEN(J639)+1),IFERROR(FIND("N",UPPER(J639)),LEN(J639)+1),IFERROR(FIND("O",UPPER(J639)),LEN(J639)+1),IFERROR(FIND("P",UPPER(J639)),LEN(J639)+1),IFERROR(FIND("Q",UPPER(J639)),LEN(J639)+1),IFERROR(FIND("R",UPPER(J639)),LEN(J639)+1),IFERROR(FIND("S",UPPER(J639)),LEN(J639)+1),IFERROR(FIND("T",UPPER(J639)),LEN(J639)+1),IFERROR(FIND("U",UPPER(J639)),LEN(J639)+1),IFERROR(FIND("V",UPPER(J639)),LEN(J639)+1),IFERROR(FIND("W",UPPER(J639)),LEN(J639)+1),IFERROR(FIND("X",UPPER(J639)),LEN(J639)+1),IFERROR(FIND("Y",UPPER(J639)),LEN(J639)+1),IFERROR(FIND("Z",UPPER(J639)),LEN(J639)+1))-1),LEFT(TEXT(I639,"0"),LEN(TEXT(I639,"0"))-3)) -> 441857089 | Y639: =IF(ISNUMBER(SEARCH("(RP)",J639)),"RP","DC") -> DC | Z639: =IF(ISNUMBER(SEARCH("(RP)",J639)),O639,IF(RIGHT(TRIM(J639),3)=", S",O639,0)) -> 0 | AA639: =IF(ISNUMBER(SEARCH("(RP)",J639)),O639,IF(RIGHT(TRIM(J639),3)=", M",O639,0)) -> 0 | AB639: =IF(ISNUMBER(SEARCH("(RP)",J639)),O639,IF(RIGHT(TRIM(J639),3)=", L",O639,0)) -> 0 | AC639: =IF(ISNUMBER(SEARCH("(RP)",J639)),O639,IF(RIGHT(TRIM(J639),4)=", XL",O639,0)) -> 0 | AD639: =IF(ISNUMBER(SEARCH("(RP)",J639)),O639,IF(OR(RIGHT(TRIM(J639),5)=", XXL",RIGHT(TRIM(J639),5)=", 2XL"),O639,0)) -> 566 | AE639: {=IFERROR(_xlfn.XLOOKUP(H639,Sheet1!$G:$G,Sheet1!$F:$F),IFERROR(_xlfn.XLOOKUP(1,(--($X$2:$X$1074=X639))*(--ISNUMBER(MATCH($H$2:$H$1074,Sheet1!$G:$G,0))),_xlfn.XLOOKUP($H$2:$H$1074,Sheet1!$G:$G,Sheet1!$F:$F,"")),"NOT FOUND"))} -> YETKRTSCUT5008 | AF639: =IFERROR(IF(ISNUMBER(SEARCH("(RP)",J639)),TRIM(SUBSTITUTE(MID(J639,10,LEN(J639)),"(RP)","")),TRIM(MID(J639,FIND(",",J639)+1,FIND(",",J639,FIND(",",J639)+1)-FIND(",",J639)-1))),"") -> OFF WHITE | AG639: =IF(A639="SZAF","Bangalore",IF(A639="SAEX","JHAJJAR",IF(A639="S0EU","HARIPAL",""))) -> Bangalore | AH639: =IF(OR(J639="",AE639="",AE639="NOT FOUND"),"",IF(Y639="RP",IFERROR(LEFT(_xlfn.XLOOKUP(AE639,Sheet1!$F:$F,Sheet1!$W:$W),FIND("-",_xlfn.XLOOKUP(AE639,Sheet1!$F:$F,Sheet1!$W:$W),FIND("-",_xlfn.XLOOKUP(AE639,Sheet1!$F:$F,Sheet1!$W:$W))+1))&AE639,"NOT FOUND"),LEFT(J639,FIND("-",J639,FIND("-",J639)+1))&AE639)) -> KRTS-APSU26-YETKRTSCUT5008
A640: SZAF | B640: 5112963768 | C640: 30.01.2026 | D640: 30.06.2026 | E640: 10337044 | F640: UNITED TEXTILE MILLS PRIVATE LIMITE | G640: 3 | H640: 8909103992453 | I640: 441857089017 | J640: KRTS-APSU26-YETKRTSCUT500, OFF WHITE, XL | L640: EA | M640: 1 | N640: 566 | O640: 566 | Q640: 0 | R640: 0 | S640: 0 | T640: 0 | U640: 0 | V640: INR | X640: =IF(ISNUMBER(VALUE(LEFT(J640,1))),LEFT(J640,MIN(IFERROR(FIND("A",UPPER(J640)),LEN(J640)+1),IFERROR(FIND("B",UPPER(J640)),LEN(J640)+1),IFERROR(FIND("C",UPPER(J640)),LEN(J640)+1),IFERROR(FIND("D",UPPER(J640)),LEN(J640)+1),IFERROR(FIND("E",UPPER(J640)),LEN(J640)+1),IFERROR(FIND("F",UPPER(J640)),LEN(J640)+1),IFERROR(FIND("G",UPPER(J640)),LEN(J640)+1),IFERROR(FIND("H",UPPER(J640)),LEN(J640)+1),IFERROR(FIND("I",UPPER(J640)),LEN(J640)+1),IFERROR(FIND("J",UPPER(J640)),LEN(J640)+1),IFERROR(FIND("K",UPPER(J640)),LEN(J640)+1),IFERROR(FIND("L",UPPER(J640)),LEN(J640)+1),IFERROR(FIND("M",UPPER(J640)),LEN(J640)+1),IFERROR(FIND("N",UPPER(J640)),LEN(J640)+1),IFERROR(FIND("O",UPPER(J640)),LEN(J640)+1),IFERROR(FIND("P",UPPER(J640)),LEN(J640)+1),IFERROR(FIND("Q",UPPER(J640)),LEN(J640)+1),IFERROR(FIND("R",UPPER(J640)),LEN(J640)+1),IFERROR(FIND("S",UPPER(J640)),LEN(J640)+1),IFERROR(FIND("T",UPPER(J640)),LEN(J640)+1),IFERROR(FIND("U",UPPER(J640)),LEN(J640)+1),IFERROR(FIND("V",UPPER(J640)),LEN(J640)+1),IFERROR(FIND("W",UPPER(J640)),LEN(J640)+1),IFERROR(FIND("X",UPPER(J640)),LEN(J640)+1),IFERROR(FIND("Y",UPPER(J640)),LEN(J640)+1),IFERROR(FIND("Z",UPPER(J640)),LEN(J640)+1))-1),LEFT(TEXT(I640,"0"),LEN(TEXT(I640,"0"))-3)) -> 441857089 | Y640: =IF(ISNUMBER(SEARCH("(RP)",J640)),"RP","DC") -> DC | Z640: =IF(ISNUMBER(SEARCH("(RP)",J640)),O640,IF(RIGHT(TRIM(J640),3)=", S",O640,0)) -> 0 | AA640: =IF(ISNUMBER(SEARCH("(RP)",J640)),O640,IF(RIGHT(TRIM(J640),3)=", M",O640,0)) -> 0 | AB640: =IF(ISNUMBER(SEARCH("(RP)",J640)),O640,IF(RIGHT(TRIM(J640),3)=", L",O640,0)) -> 0 | AC640: =IF(ISNUMBER(SEARCH("(RP)",J640)),O640,IF(RIGHT(TRIM(J640),4)=", XL",O640,0)) -> 566 | AD640: =IF(ISNUMBER(SEARCH("(RP)",J640)),O640,IF(OR(RIGHT(TRIM(J640),5)=", XXL",RIGHT(TRIM(J640),5)=", 2XL"),O640,0)) -> 0 | AE640: {=IFERROR(_xlfn.XLOOKUP(H640,Sheet1!$G:$G,Sheet1!$F:$F),IFERROR(_xlfn.XLOOKUP(1,(--($X$2:$X$1074=X640))*(--ISNUMBER(MATCH($H$2:$H$1074,Sheet1!$G:$G,0))),_xlfn.XLOOKUP($H$2:$H$1074,Sheet1!$G:$G,Sheet1!$F:$F,"")),"NOT FOUND"))} -> YETKRTSCUT5008 | AF640: =IFERROR(IF(ISNUMBER(SEARCH("(RP)",J640)),TRIM(SUBSTITUTE(MID(J640,10,LEN(J640)),"(RP)","")),TRIM(MID(J640,FIND(",",J640)+1,FIND(",",J640,FIND(",",J640)+1)-FIND(",",J640)-1))),"") -> OFF WHITE | AG640: =IF(A640="SZAF","Bangalore",IF(A640="SAEX","JHAJJAR",IF(A640="S0EU","HARIPAL",""))) -> Bangalore | AH640: =IF(OR(J640="",AE640="",AE640="NOT FOUND"),"",IF(Y640="RP",IFERROR(LEFT(_xlfn.XLOOKUP(AE640,Sheet1!$F:$F,Sheet1!$W:$W),FIND("-",_xlfn.XLOOKUP(AE640,Sheet1!$F:$F,Sheet1!$W:$W),FIND("-",_xlfn.XLOOKUP(AE640,Sheet1!$F:$F,Sheet1!$W:$W))+1))&AE640,"NOT FOUND"),LEFT(J640,FIND("-",J640,FIND("-",J640)+1))&AE640)) -> KRTS-APSU26-YETKRTSCUT5008
A641: SZAF | B641: 5112963768 | C641: 30.01.2026 | D641: 30.06.2026 | E641: 10337044 | F641: UNITED TEXTILE MILLS PRIVATE LIMITE | G641: 4 | H641: 8909103992446 | I641: 441857089018 | J641: KRTS-APSU26-YETKRTSCUT5008, OFF WHITE, L | L641: EA | M641: 1 | N641: 566 | O641: 566 | Q641: 0 | R641: 0 | S641: 0 | T641: 0 | U641: 0 | V641: INR | X641: =IF(ISNUMBER(VALUE(LEFT(J641,1))),LEFT(J641,MIN(IFERROR(FIND("A",UPPER(J641)),LEN(J641)+1),IFERROR(FIND("B",UPPER(J641)),LEN(J641)+1),IFERROR(FIND("C",UPPER(J641)),LEN(J641)+1),IFERROR(FIND("D",UPPER(J641)),LEN(J641)+1),IFERROR(FIND("E",UPPER(J641)),LEN(J641)+1),IFERROR(FIND("F",UPPER(J641)),LEN(J641)+1),IFERROR(FIND("G",UPPER(J641)),LEN(J641)+1),IFERROR(FIND("H",UPPER(J641)),LEN(J641)+1),IFERROR(FIND("I",UPPER(J641)),LEN(J641)+1),IFERROR(FIND("J",UPPER(J641)),LEN(J641)+1),IFERROR(FIND("K",UPPER(J641)),LEN(J641)+1),IFERROR(FIND("L",UPPER(J641)),LEN(J641)+1),IFERROR(FIND("M",UPPER(J641)),LEN(J641)+1),IFERROR(FIND("N",UPPER(J641)),LEN(J641)+1),IFERROR(FIND("O",UPPER(J641)),LEN(J641)+1),IFERROR(FIND("P",UPPER(J641)),LEN(J641)+1),IFERROR(FIND("Q",UPPER(J641)),LEN(J641)+1),IFERROR(FIND("R",UPPER(J641)),LEN(J641)+1),IFERROR(FIND("S",UPPER(J641)),LEN(J641)+1),IFERROR(FIND("T",UPPER(J641)),LEN(J641)+1),IFERROR(FIND("U",UPPER(J641)),LEN(J641)+1),IFERROR(FIND("V",UPPER(J641)),LEN(J641)+1),IFERROR(FIND("W",UPPER(J641)),LEN(J641)+1),IFERROR(FIND("X",UPPER(J641)),LEN(J641)+1),IFERROR(FIND("Y",UPPER(J641)),LEN(J641)+1),IFERROR(FIND("Z",UPPER(J641)),LEN(J641)+1))-1),LEFT(TEXT(I641,"0"),LEN(TEXT(I641,"0"))-3)) -> 441857089 | Y641: =IF(ISNUMBER(SEARCH("(RP)",J641)),"RP","DC") -> DC | Z641: =IF(ISNUMBER(SEARCH("(RP)",J641)),O641,IF(RIGHT(TRIM(J641),3)=", S",O641,0)) -> 0 | AA641: =IF(ISNUMBER(SEARCH("(RP)",J641)),O641,IF(RIGHT(TRIM(J641),3)=", M",O641,0)) -> 0 | AB641: =IF(ISNUMBER(SEARCH("(RP)",J641)),O641,IF(RIGHT(TRIM(J641),3)=", L",O641,0)) -> 566 | AC641: =IF(ISNUMBER(SEARCH("(RP)",J641)),O641,IF(RIGHT(TRIM(J641),4)=", XL",O641,0)) -> 0 | AD641: =IF(ISNUMBER(SEARCH("(RP)",J641)),O641,IF(OR(RIGHT(TRIM(J641),5)=", XXL",RIGHT(TRIM(J641),5)=", 2XL"),O641,0)) -> 0 | AE641: {=IFERROR(_xlfn.XLOOKUP(H641,Sheet1!$G:$G,Sheet1!$F:$F),IFERROR(_xlfn.XLOOKUP(1,(--($X$2:$X$1074=X641))*(--ISNUMBER(MATCH($H$2:$H$1074,Sheet1!$G:$G,0))),_xlfn.XLOOKUP($H$2:$H$1074,Sheet1!$G:$G,Sheet1!$F:$F,"")),"NOT FOUND"))} -> YETKRTSCUT5008 | AF641: =IFERROR(IF(ISNUMBER(SEARCH("(RP)",J641)),TRIM(SUBSTITUTE(MID(J641,10,LEN(J641)),"(RP)","")),TRIM(MID(J641,FIND(",",J641)+1,FIND(",",J641,FIND(",",J641)+1)-FIND(",",J641)-1))),"") -> OFF WHITE | AG641: =IF(A641="SZAF","Bangalore",IF(A641="SAEX","JHAJJAR",IF(A641="S0EU","HARIPAL",""))) -> Bangalore | AH641: =IF(OR(J641="",AE641="",AE641="NOT FOUND"),"",IF(Y641="RP",IFERROR(LEFT(_xlfn.XLOOKUP(AE641,Sheet1!$F:$F,Sheet1!$W:$W),FIND("-",_xlfn.XLOOKUP(AE641,Sheet1!$F:$F,Sheet1!$W:$W),FIND("-",_xlfn.XLOOKUP(AE641,Sheet1!$F:$F,Sheet1!$W:$W))+1))&AE641,"NOT FOUND"),LEFT(J641,FIND("-",J641,FIND("-",J641)+1))&AE641)) -> KRTS-APSU26-YETKRTSCUT5008
A642: SZAF | B642: 5112963768 | C642: 30.01.2026 | D642: 30.06.2026 | E642: 10337044 | F642: UNITED TEXTILE MILLS PRIVATE LIMITE | G642: 5 | H642: 8909103992439 | I642: 441857089019 | J642: KRTS-APSU26-YETKRTSCUT5008, OFF WHITE, M | L642: EA | M642: 1 | N642: 566 | O642: 566 | Q642: 0 | R642: 0 | S642: 0 | T642: 0 | U642: 0 | V642: INR | X642: =IF(ISNUMBER(VALUE(LEFT(J642,1))),LEFT(J642,MIN(IFERROR(FIND("A",UPPER(J642)),LEN(J642)+1),IFERROR(FIND("B",UPPER(J642)),LEN(J642)+1),IFERROR(FIND("C",UPPER(J642)),LEN(J642)+1),IFERROR(FIND("D",UPPER(J642)),LEN(J642)+1),IFERROR(FIND("E",UPPER(J642)),LEN(J642)+1),IFERROR(FIND("F",UPPER(J642)),LEN(J642)+1),IFERROR(FIND("G",UPPER(J642)),LEN(J642)+1),IFERROR(FIND("H",UPPER(J642)),LEN(J642)+1),IFERROR(FIND("I",UPPER(J642)),LEN(J642)+1),IFERROR(FIND("J",UPPER(J642)),LEN(J642)+1),IFERROR(FIND("K",UPPER(J642)),LEN(J642)+1),IFERROR(FIND("L",UPPER(J642)),LEN(J642)+1),IFERROR(FIND("M",UPPER(J642)),LEN(J642)+1),IFERROR(FIND("N",UPPER(J642)),LEN(J642)+1),IFERROR(FIND("O",UPPER(J642)),LEN(J642)+1),IFERROR(FIND("P",UPPER(J642)),LEN(J642)+1),IFERROR(FIND("Q",UPPER(J642)),LEN(J642)+1),IFERROR(FIND("R",UPPER(J642)),LEN(J642)+1),IFERROR(FIND("S",UPPER(J642)),LEN(J642)+1),IFERROR(FIND("T",UPPER(J642)),LEN(J642)+1),IFERROR(FIND("U",UPPER(J642)),LEN(J642)+1),IFERROR(FIND("V",UPPER(J642)),LEN(J642)+1),IFERROR(FIND("W",UPPER(J642)),LEN(J642)+1),IFERROR(FIND("X",UPPER(J642)),LEN(J642)+1),IFERROR(FIND("Y",UPPER(J642)),LEN(J642)+1),IFERROR(FIND("Z",UPPER(J642)),LEN(J642)+1))-1),LEFT(TEXT(I642,"0"),LEN(TEXT(I642,"0"))-3)) -> 441857089 | Y642: =IF(ISNUMBER(SEARCH("(RP)",J642)),"RP","DC") -> DC | Z642: =IF(ISNUMBER(SEARCH("(RP)",J642)),O642,IF(RIGHT(TRIM(J642),3)=", S",O642,0)) -> 0 | AA642: =IF(ISNUMBER(SEARCH("(RP)",J642)),O642,IF(RIGHT(TRIM(J642),3)=", M",O642,0)) -> 566 | AB642: =IF(ISNUMBER(SEARCH("(RP)",J642)),O642,IF(RIGHT(TRIM(J642),3)=", L",O642,0)) -> 0 | AC642: =IF(ISNUMBER(SEARCH("(RP)",J642)),O642,IF(RIGHT(TRIM(J642),4)=", XL",O642,0)) -> 0 | AD642: =IF(ISNUMBER(SEARCH("(RP)",J642)),O642,IF(OR(RIGHT(TRIM(J642),5)=", XXL",RIGHT(TRIM(J642),5)=", 2XL"),O642,0)) -> 0 | AE642: {=IFERROR(_xlfn.XLOOKUP(H642,Sheet1!$G:$G,Sheet1!$F:$F),IFERROR(_xlfn.XLOOKUP(1,(--($X$2:$X$1074=X642))*(--ISNUMBER(MATCH($H$2:$H$1074,Sheet1!$G:$G,0))),_xlfn.XLOOKUP($H$2:$H$1074,Sheet1!$G:$G,Sheet1!$F:$F,"")),"NOT FOUND"))} -> YETKRTSCUT5008 | AF642: =IFERROR(IF(ISNUMBER(SEARCH("(RP)",J642)),TRIM(SUBSTITUTE(MID(J642,10,LEN(J642)),"(RP)","")),TRIM(MID(J642,FIND(",",J642)+1,FIND(",",J642,FIND(",",J642)+1)-FIND(",",J642)-1))),"") -> OFF WHITE | AG642: =IF(A642="SZAF","Bangalore",IF(A642="SAEX","JHAJJAR",IF(A642="S0EU","HARIPAL",""))) -> Bangalore | AH642: =IF(OR(J642="",AE642="",AE642="NOT FOUND"),"",IF(Y642="RP",IFERROR(LEFT(_xlfn.XLOOKUP(AE642,Sheet1!$F:$F,Sheet1!$W:$W),FIND("-",_xlfn.XLOOKUP(AE642,Sheet1!$F:$F,Sheet1!$W:$W),FIND("-",_xlfn.XLOOKUP(AE642,Sheet1!$F:$F,Sheet1!$W:$W))+1))&AE642,"NOT FOUND"),LEFT(J642,FIND("-",J642,FIND("-",J642)+1))&AE642)) -> KRTS-APSU26-YETKRTSCUT5008
